Workbook

Sheet Instruções
A1: Catálogo de mitigações (C2): planilha de trabalho
A3: Objetivo | B3: Selecionar 40 mitigações da base de Saeri et al. (MIT AI Risk Initiative) aplicáveis a organizações que implantam ou operam sistemas de IA, e completar os campos de contribuição do grupo. Decisão 0024.
A4: Fonte | B4: AI Risk Mitigation Database, MIT AI Risk Initiative (airisk.mit.edu), versão pública de 2025-07-23 (arquivo _PUBLIC__Mitigation_Database_2025-07-23.csv). As 831 entradas já estão carregadas na folha Triagem, ordenadas pelos grupos de documentos. Dados sob licença CC BY 4.0: dar o crédito e indicar as alterações (tradução e adaptação).
A5: Passo 1. Triagem | B5: As entradas da base já estão na folha Triagem. O critério Classificada já vem preenchido, por ser objetivo (as 16 sem subcategoria, com código terminado em X, ficam com Não). Cada membro analisa o seu bloco e marca os outros três critérios. A coluna Elegível é calculada.
A6: Passo 2. Seleção | B6: Entre as elegíveis, escolha 40, 10 por membro, respeitando a cobertura da folha Acompanhamento: as subcategorias aplicáveis representadas e cada domínio de risco do MIT com 3 mitigações ou mais. Marque Incluir nelas e Excluir, com motivo, nas demais.
A7: Passo 3. Catálogo | B7: Para cada entrada incluída, preencha a folha Catálogo. Os campos de Saeri (ID, nome original, documento, subcategoria) são copiados da triagem; os demais são contribuição do grupo.
A8: Passo 4. Anotação dupla | B8: Cada mitigação tem dois anotadores, de membros diferentes, para os subdomínios de risco. O anotador B preenche sem ver a coluna do anotador A (oculte-a antes de começar). Depois, os dois discutem as divergências e registram o consenso. Essa anotação dupla é a base da medida de concordância do OE1.
A9: Passo 5. Estimativas | B9: Custo, evidência e concordância seguem a folha Rubrica. A incerteza é calculada. Registre na Fonte da estimativa de onde veio cada avaliação.
A10: Critérios de inclusão | B10: Ator: aplicável a quem implanta ou opera sistemas de IA. Acionável: ação concreta, não condição organizacional. Verificável: há evidência que comprove a aplicação. Classificada: tem subcategoria (não é X.X). As quatro condições são obrigatórias.
A11: Redundância | B11: Quando várias entradas descrevem a mesma ação, escolha uma representativa e registre o ID dela na coluna 'Redundante com' das demais. Não funda entradas: a rastreabilidade até a base depende do ID.
A12: Formato dos subdomínios | B12: Códigos do MIT separados por vírgula e espaço, em ordem crescente: 1.1, 7.3. A ordem importa para o cálculo de concordância exata.
A13: Fonte da estimativa | B13: Modelo de preenchimento [Fontes consultadas], [o que cada uma sustenta]. [O que é julgamento do grupo]. Regras: - Cite só fontes que você abriu e conferiu. Se usar IA para achar fontes, confira cada uma: a IA inventa referências com facilidade. - A fonte original da mitigação (o documento de Saeri) sustenta o que a mitigação é, mas raramente sustenta custo. - Quando não houver fonte externa para alguma estimativa, usaremos esta resposta como padrão: "Custo estimado pelo grupo, pela rubrica." Isso é legítimo; o que não pode é esconder. - Coerência com a rubrica: se a única base for o julgamento do grupo, a evidência é Limitada. Se houver mais de uma fonte, ou uma norma ou guia reconhecido, sem dado empírico, é Média. Robusta exige várias fontes independentes com estudo empírico ou avaliação publicada.
A14: Uso de IA | B14: Permitido como apoio, com validação humana integral de cada entrada, e registrado na coluna Assistência de IA. Saeri et al. relatam que assistentes de IA omitiram, fundiram e inventaram mitigações durante a extração.
... A29: Classificada | B29: Sim
A30: Redundante com (ID)
A31: Elegível | B31: Sim (calculado)
A32: Decisão | B32: Incluir
A33: Motivo da exclusão
A34: Assistência de IA | B34: Não
A35: Observações | B35: Representativa de outras duas entradas equivalentes.
A37: Exemplo ilustrativo de linha do Catálogo | B37: Valores fictícios, só para mostrar o formato.
A38: Nº | B38: 1
A39: Responsável | B39: Renato Pestana de Gouveia
A40: ID na base | B40: (ID da base)
A41: Nome original | B41: Incident response plan
A42: Nome em português | B42: Plano de resposta a incidentes
A43: Documento de origem | B43: NIST AI RMF: Generative AI Profile (NIST, 2024)
A44: Subcategoria (Saeri) | B44: 3.6 Resposta a incidentes e recuperação
A45: Descrição em português | B45: Estabelecer um plano de resposta a incidentes de IA, com papéis, escalonamento e etapas de recuperação.
A46: Subdomínios: anotador A | B46: 3.1, 7.3
... A59: Situação | B59: Concluída
A60: Observações
A61: Chave do documento | B61: nist-2024 (calculado)
A62: Código da subcategoria | B62: 3.6 (calculado)

Sheet Triagem
A1: ID na base | B1: Nome original | C1: Descrição original | D1: Documento de origem | E1: Subcategoria (Saeri) | F1: Responsável | G1: Ator | H1: Acionável | I1: Verificável | J1: Classificada | K1: Redundante com (ID) | L1: Elegível | M1: Decisão | N1: Motivo da exclusão | O1: Assistência de IA | P1: Observações | Q1: IA: Ator | R1: IA: Acionável | S1: IA: Verificável | T1: IA: Classificada | U1: IA: Elegível | V1: IA: Justificativa | W1: IA: Possíveis redundâncias
A2: A0388_NIST2024 | B2: Legal Compliance Alignment | C2: Align GAI development and use with applicable laws and regulations, including those related to data privacy, copyright and intellectual property law. | D2: NIST AI RMF: Generative AI Profile (NIST, 2024) | E2: 4.1 Documentação do sistema | F2: Angelo Andrioli Netho | G2: Sim | H2: Não | I2: Não | J2: Sim | L2: =IF(COUNTA(G2:J2)<4,"",IF(AND(G2="Sim",H2="Sim",I2="Sim",J2="Sim",K2=""),"Sim","Não")) -> Não | O2: Sim | Q2: Sim | R2: Não | S2: Não | T2: Sim | U2: Não | V2: Diretriz genérica, princípio ou condição organizacional, sem ação concreta definida.
A3: A0389_NIST2024 | B3: Training Data Transparency | C3: Establish transparency policies and processes for documenting the origin and history of training data and generated data for GAI applications to advance digital content transparency, while balancing the proprietary nature of training approaches. | D3: NIST AI RMF: Generative AI Profile (NIST, 2024) | E3: 3.2 Governança de dados | F3: Angelo Andrioli Netho | G3: Sim | H3: Sim | I3: Sim | J3: Sim | K3: A0460; A0527 | L3: =IF(COUNTA(G3:J3)<4,"",IF(AND(G3="Sim",H3="Sim",I3="Sim",J3="Sim",K3=""),"Sim","Não")) -> Não | O3: Sim | Q3: Sim | R3: Sim | S3: Sim | T3: Sim | U3: Sim | V3: Aplicável a quem implanta ou opera sistemas de IA; ação concreta e comprovável. | W3: A0460_NIST2024 Transparency Training Adaptation (0,24); A0527_NIST2024 Digital Content Transparency (0,18)
A4: A0390_NIST2024 | B4: Risk Capability Evaluation | C4: Establish policies to evaluate risk-relevant capabilities of GAI and robustness of safety measures, both prior to deployment and on an ongoing basis, through internal and external evaluations. | D4: NIST AI RMF: Generative AI Profile (NIST, 2024) | E4: 3.1 Testes e auditoria | F4: Angelo Andrioli Netho | G4: Sim | H4: Sim | I4: Sim | J4: Sim | L4: =IF(COUNTA(G4:J4)<4,"",IF(AND(G4="Sim",H4="Sim",I4="Sim",J4="Sim",K4=""),"Sim","Não")) -> Sim | O4: Sim | Q4: Sim | R4: Sim | S4: Sim | T4: Sim | U4: Sim | V4: Aplicável a quem implanta ou opera sistemas de IA; ação concreta e comprovável.
A5: A0391_NIST2024 | B5: Risk Tier Definition | C5: Consider the following factors when updating or defining risk tiers for GAI: Abuses and impacts to information integrity; Dependencies between GAI and other IT or data systems; Harm to fundamental rights or public safety; Presentation of obscene, objectionable, offensive, discriminatory, invalid or untruthful output; Psychological impacts to humans (e.g., anthropomorphization, algorithmic aversion, emotional entanglement); Possibility for malicious use; Whether the system introduces significant new security vulnerabilities; Anticipated system impact on some groups compared to others; Unreliable decision making capabilities, validity, adaptability, and variability of GAI system performance over time. | D5: NIST AI RMF: Generative AI Profile (NIST, 2024) | E5: 1.2 Gestão de riscos | F5: Angelo Andrioli Netho | G5: Sim | H5: Sim | I5: Sim | J5: Sim | L5: =IF(COUNTA(G5:J5)<4,"",IF(AND(G5="Sim",H5="Sim",I5="Sim",J5="Sim",K5=""),"Sim","Não")) -> Sim | O5: Sim | Q5: Sim | R5: Sim | S5: Sim | T5: Sim | U5: Sim | V5: Redigida como consideração ou pergunta; a ação subjacente é concreta e aplicável, mas a descrição precisa ser reescrita como ação.
A6: A0392_NIST2024 | B6: Performance Threshold Standards | C6: Establish minimum thresholds for performance or assurance criteria and review as part of deployment approval ("go/"no-go") policies, procedures, and processes, with reviewed processes and approval thresholds reflecting measurement of GAI capabilities and risks. | D6: NIST AI RMF: Generative AI Profile (NIST, 2024) | E6: 1.5 Estruturas de decisão de segurança | F6: Angelo Andrioli Netho | G6: Sim | H6: Sim | I6: Sim | J6: Sim | L6: =IF(COUNTA(G6:J6)<4,"",IF(AND(G6="Sim",H6="Sim",I6="Sim",J6="Sim",K6=""),"Sim","Não")) -> Sim | O6: Sim | Q6: Sim | R6: Sim | S6: Sim | T6: Sim | U6: Sim | V6: Aplicável a quem implanta ou opera sistemas de IA; ação concreta e comprovável.
A7: A0393_NIST2024 | B7: CBRN Testing Protocol | C7: Establish a test plan and response policy, before developing highly capable models, to periodically evaluate whether the model may misuse CBRN information or capabilities and/or offensive cyber capabilities. | D7: NIST AI RMF: Generative AI Profile (NIST, 2024) | E7: 3.1 Testes e auditoria | F7: Angelo Andrioli Netho | G7: Não | H7: Sim | I7: Sim | J7: Sim | L7: =IF(COUNTA(G7:J7)<4,"",IF(AND(G7="Sim",H7="Sim",I7="Sim",J7="Sim",K7=""),"Sim","Não")) -> Não | O7: Sim | Q7: Não | R7: Sim | S7: Sim | T7: Sim | U7: Não | V7: Voltada a quem desenvolve ou treina modelos de fronteira (capacidades perigosas, treinamento em larga escala, pesos, escalonamento); pouco aplicável a quem implanta ou opera.
A8: A0394_NIST2024 | B8: Stakeholder Input Collection | C8: Obtain input from stakeholder communities to identify unacceptable use, in accordance with activities in the AI RMF Map function. | D8: NIST AI RMF: Generative AI Profile (NIST, 2024) | E8: 1.7 Avaliação de impacto social | F8: Angelo Andrioli Netho | G8: Sim | H8: Sim | I8: Sim | J8: Sim | L8: =IF(COUNTA(G8:J8)<4,"",IF(AND(G8="Sim",H8="Sim",I8="Sim",J8="Sim",K8=""),"Sim","Não")) -> Sim | O8: Sim | Q8: Sim | R8: Sim | S8: Sim | T8: Sim | U8: Sim | V8: Aplicável a quem implanta ou opera sistemas de IA; ação concreta e comprovável.
A9: A0395_NIST2024 | B9: Risk Hierarchy Maintenance | C9: Maintain an updated hierarchy of identified and expected GAI risks connected to contexts of GAI model advancement and use, potentially including specialized risk levels for GAI systems that address issues such as model collapse and algorithmic monoculture. | D9: NIST AI RMF: Generative AI Profile (NIST, 2024) | E9: 1.2 Gestão de riscos | F9: Angelo Andrioli Netho | G9: Sim | H9: Sim | I9: Sim | J9: Sim | L9: =IF(COUNTA(G9:J9)<4,"",IF(AND(G9="Sim",H9="Sim",I9="Sim",J9="Sim",K9=""),"Sim","Não")) -> Sim | O9: Sim | Q9: Sim | R9: Sim | S9: Sim | T9: Sim | U9: Sim | V9: Aplicável a quem implanta ou opera sistemas de IA; ação concreta e comprovável.
A10: A0396_NIST2024 | B10: Risk Tolerance Reassessment | C10: Reevaluate organizational risk tolerances to account for unacceptable negative risk (such as where significant negative impacts are imminent, severe harms are actually occurring, or large-scale risks could occur); and broad GAI negative risks, including: Immature safety or risk cultures related to AI and GAI design, development and deployment, public information integrity risks, including impacts on democratic processes, unknown long-term performance characteristics of GAI. | D10: NIST AI RMF: Generative AI Profile (NIST, 2024) | E10: 1.2 Gestão de riscos | F10: Angelo Andrioli Netho | G10: Sim | H10: Sim | I10: Sim | J10: Sim | K10: A0656 | L10: =IF(COUNTA(G10:J10)<4,"",IF(AND(G10="Sim",H10="Sim",I10="Sim",J10="Sim",K10=""),"Sim","Não")) -> Não | O10: Sim | Q10: Sim | R10: Sim | S10: Sim | T10: Sim | U10: Sim | V10: Aplicável a quem implanta ou opera sistemas de IA; ação concreta e comprovável. | W10: A0656_Barrett2024 Risk Tolerance Thresholds (0,16)
A11: A0397_NIST2024 | B11: Development Halt Plan | C11: Devise a plan to halt development or deployment of a GAI system that poses unacceptable negative risk. | D11: NIST AI RMF: Generative AI Profile (NIST, 2024) | E11: 1.5 Estruturas de decisão de segurança | F11: Angelo Andrioli Netho | G11: Sim | H11: Sim | I11: Sim | J11: Sim | L11: =IF(COUNTA(G11:J11)<4,"",IF(AND(G11="Sim",H11="Sim",I11="Sim",J11="Sim",K11=""),"Sim","Não")) -> Sim | M11: Incluir | O11: Sim | Q11: Sim | R11: Sim | S11: Sim | T11: Sim | U11: Sim | V11: Aplicável a quem implanta ou opera sistemas de IA; ação concreta e comprovável.
A12: A0398_NIST2024 | B12: Harmful Content Prevention | C12: Establish policies and mechanisms to prevent GAI systems from generating CSAM, NCII or content that violates the law. | D12: NIST AI RMF: Generative AI Profile (NIST, 2024) | E12: 2.4 Controles de segurança de conteúdo | F12: Angelo Andrioli Netho | G12: Sim | H12: Sim | I12: Sim | J12: Sim | L12: =IF(COUNTA(G12:J12)<4,"",IF(AND(G12="Sim",H12="Sim",I12="Sim",J12="Sim",K12=""),"Sim","Não")) -> Sim | M12: Incluir | O12: Sim | Q12: Sim | R12: Sim | S12: Sim | T12: Sim | U12: Sim | V12: Aplicável a quem implanta ou opera sistemas de IA; ação concreta e comprovável.
A13: A0399_NIST2024 | B13: Acceptable Use Policy | C13: Establish transparent acceptable use policies for GAI that address illegal use or applications of GAI. | D13: NIST AI RMF: Generative AI Profile (NIST, 2024) | E13: 3.3 Gestão de acesso | F13: Angelo Andrioli Netho | G13: Sim | H13: Sim | I13: Sim | J13: Sim | K13: A0415; A0436; A0447 | L13: =IF(COUNTA(G13:J13)<4,"",IF(AND(G13="Sim",H13="Sim",I13="Sim",J13="Sim",K13=""),"Sim","Não")) -> Não | O13: Sim | Q13: Sim | R13: Sim | S13: Sim | T13: Sim | U13: Sim | V13: Aplicável a quem implanta ou opera sistemas de IA; ação concreta e comprovável. | W13: A0415_NIST2024 Interface Use Policy (0,31); A0436_NIST2024 Third-Party Use Policy Update (0,30); A0447_NIST2024 Illegal Use Identification (0,21)
A14: A0400_NIST2024 | B14: Content Provenance Review | C14: Define organizational responsibilities for periodic review of content provenance and incident monitoring for GAI systems. | D14: NIST AI RMF: Generative AI Profile (NIST, 2024) | E14: 3.5 Monitoramento pós-implantação | F14: Angelo Andrioli Netho | G14: Sim | H14: Sim | I14: Sim | J14: Sim | K14: A0637 | L14: =IF(COUNTA(G14:J14)<4,"",IF(AND(G14="Sim",H14="Sim",I14="Sim",J14="Sim",K14=""),"Sim","Não")) -> Não | O14: Sim | Q14: Sim | R14: Sim | S14: Sim | T14: Sim | U14: Sim | V14: Aplicável a quem implanta ou opera sistemas de IA; ação concreta e comprovável. | W14: A0637_Barrett2024 Monitoring of RM policies (0,19)
A15: A0401_NIST2024 | B15: Incident Response Process | C15: Establish organizational policies and procedures for after action reviews of GAI system incident response and incident disclosures, to identify gaps; Update incident response and incident disclosure processes as required. | D15: NIST AI RMF: Generative AI Profile (NIST, 2024) | E15: 3.6 Resposta a incidentes e recuperação | F15: Angelo Andrioli Netho | G15: Sim | H15: Sim | I15: Sim | J15: Sim | K15: A0409; A0439; A0209; | L15: =IF(COUNTA(G15:J15)<4,"",IF(AND(G15="Sim",H15="Sim",I15="Sim",J15="Sim",K15=""),"Sim","Não")) -> Não | O15: Sim | Q15: Sim | R15: Sim | S15: Sim | T15: Sim | U15: Sim | V15: Aplicável a quem implanta ou opera sistemas de IA; ação concreta e comprovável. | W15: A0409_NIST2024 Incident Response Teams (0,24); A0439_NIST2024 Third-Party Response Plans (0,20); A0209_Schuett2023 Security incident response plan (0,19)
A16: A0402_NIST2024 | B16: Documentation Retention Policy | C16: Maintain a document retention policy to keep history for test, evaluation, validation, and verification (TEVV), and digital content transparency methods for GAI. | D16: NIST AI RMF: Generative AI Profile (NIST, 2024) | E16: 4.1 Documentação do sistema | F16: Angelo Andrioli Netho | G16: Sim | H16: Sim | I16: Sim | J16: Sim | K16: A0527 | L16: =IF(COUNTA(G16:J16)<4,"",IF(AND(G16="Sim",H16="Sim",I16="Sim",J16="Sim",K16=""),"Sim","Não")) -> Não | O16: Sim | Q16: Sim | R16: Sim | S16: Sim | T16: Sim | U16: Sim | V16: Aplicável a quem implanta ou opera sistemas de IA; ação concreta e comprovável. | W16: A0527_NIST2024 Digital Content Transparency (0,16)
A17: A0403_NIST2024 | B17: System Inventory Enumeration | C17: Enumerate organizational GAI systems for incorporation into AI system inventory and adjust AI system inventory requirements to account for GAI risks. | D17: NIST AI RMF: Generative AI Profile (NIST, 2024) | E17: 1.2 Gestão de riscos | F17: Angelo Andrioli Netho | G17: Sim | H17: Sim | I17: Sim | J17: Sim | K17: A0638; A0404; | L17: =IF(COUNTA(G17:J17)<4,"",IF(AND(G17="Sim",H17="Sim",I17="Sim",J17="Sim",K17=""),"Sim","Não")) -> Não | O17: Sim | Q17: Sim | R17: Sim | S17: Sim | T17: Sim | U17: Sim | V17: Aplicável a quem implanta ou opera sistemas de IA; ação concreta e comprovável. | W17: A0638_Barrett2024 Inventory AI Systems (0,18); A0404_NIST2024 Inventory Exemption Definition (0,16)
A18: A0404_NIST2024 | B18: Inventory Exemption Definition | C18: Define any inventory exemptions in organizational policies for GAI systems embedded into application software. | D18: NIST AI RMF: Generative AI Profile (NIST, 2024) | E18: 1.2 Gestão de riscos | F18: Angelo Andrioli Netho | G18: Sim | H18: Sim | I18: Sim | J18: Sim | K18: A0403; A0638; | L18: =IF(COUNTA(G18:J18)<4,"",IF(AND(G18="Sim",H18="Sim",I18="Sim",J18="Sim",K18=""),"Sim","Não")) -> Não | O18: Sim | Q18: Sim | R18: Sim | S18: Sim | T18: Sim | U18: Sim | V18: Aplicável a quem implanta ou opera sistemas de IA; ação concreta e comprovável. | W18: A0403_NIST2024 System Inventory Enumeration (0,16); A0638_Barrett2024 Inventory AI Systems (0,15)
A19: A0405_NIST2024 | B19: Comprehensive Inventory Details | C19: In addition to general model, governance, and risk information, consider the following items in GAI system inventory entries: Data provenance information (e.g., source, signatures, versioning, watermarks); Known issues reported from internal bug tracking or external information sharing resources (e.g., AI incident database, AVID, CVE, NVD, or OECD AI incident monitor); Human oversight roles and responsibilities; Special rights and considerations for intellectual property, licensed works, or personal, privileged, proprietary or sensitive data; Underlying foundation models, versions of underlying models, and access modes. | D19: NIST AI RMF: Generative AI Profile (NIST, 2024) | E19: 4.1 Documentação do sistema | F19: Angelo Andrioli Netho | G19: Sim | H19: Sim | I19: Sim | J19: Sim | K19: A0408 | L19: =IF(COUNTA(G19:J19)<4,"",IF(AND(G19="Sim",H19="Sim",I19="Sim",J19="Sim",K19=""),"Sim","Não")) -> Não | O19: Sim | Q19: Sim | R19: Sim | S19: Sim | T19: Sim | U19: Sim | V19: Aplicável a quem implanta ou opera sistemas de IA; ação concreta e comprovável. | W19: A0408_NIST2024 Incident Communication Framework (0,23)
A20: A0406_NIST2024 | B20: Deactivation Protocol | C20: Protocols are put in place to ensure GAI systems are able to be deactivated when necessary. | D20: NIST AI RMF: Generative AI Profile (NIST, 2024) | E20: 3.6 Resposta a incidentes e recuperação | F20: Angelo Andrioli Netho | G20: Sim | H20: Sim | I20: Sim | J20: Sim | L20: =IF(COUNTA(G20:J20)<4,"",IF(AND(G20="Sim",H20="Sim",I20="Sim",J20="Sim",K20=""),"Sim","Não")) -> Sim | O20: Sim | Q20: Sim | R20: Sim | S20: Sim | T20: Sim | U20: Sim | V20: Aplicável a quem implanta ou opera sistemas de IA; ação concreta e comprovável.
A21: A0407_NIST2024 | B21: Decommissioning Considerations | C21: Consider the following factors when decommissioning GAI systems: Data retention requirements; Data security, e.g., containment, protocols, Data leakage after decommissioning; Dependencies between upstream, downstream, or other data, internet of things (IOT) or AI systems; Use of open-source data or models; Users' emotional entanglement with GAI functions. | D21: NIST AI RMF: Generative AI Profile (NIST, 2024) | E21: 3.2 Governança de dados | F21: Angelo Andrioli Netho | G21: Sim | H21: Sim | I21: Sim | J21: Sim | L21: =IF(COUNTA(G21:J21)<4,"",IF(AND(G21="Sim",H21="Sim",I21="Sim",J21="Sim",K21=""),"Sim","Não")) -> Sim | O21: Sim | Q21: Sim | R21: Sim | S21: Sim | T21: Sim | U21: Sim | V21: Redigida como consideração ou pergunta; a ação subjacente é concreta e aplicável, mas a descrição precisa ser reescrita como ação.
A22: A0408_NIST2024 | B22: Incident Communication Framework | C22: Establish organizational roles, policies, and procedures for communicating GAI incidents and performance to AI Actors and downstream stakeholders (including those potentially impacted), via community or official resources (e.g., AI incident database, AVID, CVE, NVD, or OECD AI incident monitor). | D22: NIST AI RMF: Generative AI Profile (NIST, 2024) | E22: 4.3 Relato de incidentes | F22: Angelo Andrioli Netho | G22: Sim | H22: Sim | I22: Sim | J22: Sim | K22: A0405 | L22: =IF(COUNTA(G22:J22)<4,"",IF(AND(G22="Sim",H22="Sim",I22="Sim",J22="Sim",K22=""),"Sim","Não")) -> Não | O22: Sim | Q22: Sim | R22: Sim | S22: Sim | T22: Sim | U22: Sim | V22: Aplicável a quem implanta ou opera sistemas de IA; ação concreta e comprovável. | W22: A0405_NIST2024 Comprehensive Inventory Details (0,23)
A23: A0409_NIST2024 | B23: Incident Response Teams | C23: Establish procedures to engage teams for GAI system incident response with diverse composition and responsibilities based on the particular incident type. | D23: NIST AI RMF: Generative AI Profile (NIST, 2024) | E23: 3.6 Resposta a incidentes e recuperação | F23: Angelo Andrioli Netho | G23: Sim | H23: Sim | I23: Sim | J23: Sim | K23: A0401; A0439; A0209; | L23: =IF(COUNTA(G23:J23)<4,"",IF(AND(G23="Sim",H23="Sim",I23="Sim",J23="Sim",K23=""),"Sim","Não")) -> Não | O23: Sim | Q23: Sim | R23: Sim | S23: Sim | T23: Sim | U23: Sim | V23: Aplicável a quem implanta ou opera sistemas de IA; ação concreta e comprovável. | W23: A0401_NIST2024 Incident Response Process (0,24); A0439_NIST2024 Third-Party Response Plans (0,20); A0209_Schuett2023 Security incident response plan (0,18)
A24: A0410_NIST2024 | B24: Response Team Verification | C24: Establish processes to verify the AI Actors conducting GAI incident response tasks demonstrate and maintain the appropriate skills and training. | D24: NIST AI RMF: Generative AI Profile (NIST, 2024) | E24: 3.6 Resposta a incidentes e recuperação | F24: Angelo Andrioli Netho | G24: Sim | H24: Sim | I24: Sim | J24: Sim | K24: A0401; A0409; | L24: =IF(COUNTA(G24:J24)<4,"",IF(AND(G24="Sim",H24="Sim",I24="Sim",J24="Sim",K24=""),"Sim","Não")) -> Não | O24: Sim | Q24: Sim | R24: Sim | S24: Sim | T24: Sim | U24: Sim | V24: Aplicável a quem implanta ou opera sistemas de IA; ação concreta e comprovável. | W24: A0401_NIST2024 Incident Response Process (0,16); A0409_NIST2024 Incident Response Teams (0,15)
A25: A0411_NIST2024 | B25: National Security Involvement | C25: When systems may raise national security risks, involve national security professionals in mapping, measuring, and managing those risks. | D25: NIST AI RMF: Generative AI Profile (NIST, 2024) | E25: 4.2 Divulgação de riscos | F25: Angelo Andrioli Netho | G25: Sim | H25: Sim | I25: Sim | J25: Sim | L25: =IF(COUNTA(G25:J25)<4,"",IF(AND(G25="Sim",H25="Sim",I25="Sim",J25="Sim",K25=""),"Sim","Não")) -> Sim | O25: Sim | Q25: Não | R25: Sim | S25: Sim | T25: Sim | U25: Não | V25: Voltada a quem desenvolve ou treina modelos de fronteira (capacidades perigosas, treinamento em larga escala, pesos, escalonamento); pouco aplicável a quem implanta ou opera.
A26: A0412_NIST2024 | B26: Whistleblower Protection | C26: Create mechanisms to provide protections for whistleblowers who report, based on reasonable belief, when the organization violates relevant laws or poses a specific and empirically well-substantiated negative risk to public safety (or has already caused harm). | D26: NIST AI RMF: Generative AI Profile (NIST, 2024) | E26: 1.4 Canal de denúncia e proteção ao denunciante | F26: Angelo Andrioli Netho | G26: Sim | H26: Sim | I26: Sim | J26: Sim | K26: A0022; A1044; A0104; | L26: =IF(COUNTA(G26:J26)<4,"",IF(AND(G26="Sim",H26="Sim",I26="Sim",J26="Sim",K26=""),"Sim","Não")) -> Não | O26: Sim | Q26: Sim | R26: Sim | S26: Sim | T26: Sim | U26: Sim | V26: Aplicável a quem implanta ou opera sistemas de IA; ação concreta e comprovável. | W26: A0022_Bengio2025 Whistleblower protection (0,23); A1044_Uuk2024 Whistleblower protections (0,18); A0104_Future of Life Institute2024 Comprehensive whistleblower protection policy (0,18)
A27: A0413_NIST2024 | B27: Independent Evaluation Policy | C27: Policies are in place to bolster oversight of GAI systems with independent evaluations or assessments of GAI models or systems where the type and robustness of evaluations are proportional to the identified risks. | D27: NIST AI RMF: Generative AI Profile (NIST, 2024) | E27: 3.1 Testes e auditoria | F27: Angelo Andrioli Netho | G27: Sim | H27: Sim | I27: Sim | J27: Sim | L27: =IF(COUNTA(G27:J27)<4,"",IF(AND(G27="Sim",H27="Sim",I27="Sim",J27="Sim",K27=""),"Sim","Não")) -> Sim | O27: Sim | Q27: Sim | R27: Sim | S27: Sim | T27: Sim | U27: Sim | V27: Aplicável a quem implanta ou opera sistemas de IA; ação concreta e comprovável.
A28: A0414_NIST2024 | B28: Organizational Role Adjustment | C28: Consider adjustment of organizational roles and components across lifecycle stages of large or complex GAI systems, including: Test and evaluation, validation, and red-teaming of GAI systems; GAI content moderation; GAI system development and engineering; Increased accessibility of GAI tools, interfaces, and systems, Incident response and containment. | D28: NIST AI RMF: Generative AI Profile (NIST, 2024) | E28: 1.1 Estrutura de conselho e supervisão | F28: Angelo Andrioli Netho | G28: Sim | H28: Não | I28: Não | J28: Sim | L28: =IF(COUNTA(G28:J28)<4,"",IF(AND(G28="Sim",H28="Sim",I28="Sim",J28="Sim",K28=""),"Sim","Não")) -> Não | O28: Sim | Q28: Sim | R28: Não | S28: Não | T28: Sim | U28: Não | V28: Diretriz genérica, princípio ou condição organizacional, sem ação concreta definida.
A29: A0415_NIST2024 | B29: Interface Use Policy | C29: Define acceptable use policies for GAI interfaces, modalities, and human-AI configurations (i.e., for chatbots and decision-making tasks), including criteria for the kinds of queries GAI applications should refuse to respond to. | D29: NIST AI RMF: Generative AI Profile (NIST, 2024) | E29: 3.3 Gestão de acesso | F29: Angelo Andrioli Netho | G29: Sim | H29: Sim | I29: Sim | J29: Sim | K29: A0399; A0436; | L29: =IF(COUNTA(G29:J29)<4,"",IF(AND(G29="Sim",H29="Sim",I29="Sim",J29="Sim",K29=""),"Sim","Não")) -> Não | O29: Sim | Q29: Sim | R29: Sim | S29: Sim | T29: Sim | U29: Sim | V29: Aplicável a quem implanta ou opera sistemas de IA; ação concreta e comprovável. | W29: A0399_NIST2024 Acceptable Use Policy (0,31); A0436_NIST2024 Third-Party Use Policy Update (0,18)
A30: A0416_NIST2024 | B30: User Feedback Mechanism | C30: Establish policies for user feedback mechanisms for GAI systems which include thorough instructions and any mechanisms for recourse. | D30: NIST AI RMF: Generative AI Profile (NIST, 2024) | E30: 4.6 Direitos e recursos dos usuários | F30: Angelo Andrioli Netho | G30: Sim | H30: Sim | I30: Sim | J30: Sim | K30: A0687 | L30: =IF(COUNTA(G30:J30)<4,"",IF(AND(G30="Sim",H30="Sim",I30="Sim",J30="Sim",K30=""),"Sim","Não")) -> Não | O30: Sim | Q30: Sim | R30: Sim | S30: Sim | T30: Sim | U30: Sim | V30: Aplicável a quem implanta ou opera sistemas de IA; ação concreta e comprovável. | W30: A0687_Barrett2024 Enable User Feedback & Appeals (0,16)
A31: A0417_NIST2024 | B31: Threat Modeling Process | C31: Engage in threat modeling to anticipate potential risks from GAI systems | D31: NIST AI RMF: Generative AI Profile (NIST, 2024) | E31: 2.3 Engenharia de segurança do modelo | F31: Angelo Andrioli Netho | G31: Sim | H31: Sim | I31: Sim | J31: Sim | L31: =IF(COUNTA(G31:J31)<4,"",IF(AND(G31="Sim",H31="Sim",I31="Sim",J31="Sim",K31=""),"Sim","Não")) -> Sim | O31: Sim | Q31: Sim | R31: Sim | S31: Sim | T31: Sim | U31: Sim | V31: Aplicável a quem implanta ou opera sistemas de IA; ação concreta e comprovável.
A32: A0418_NIST2024 | B32: Risk Measurement Improvement | C32: Establish policies and procedures that address continual improvement processes for GAI risk measurement. Address general risks associated with a lack of explainability and transparency in GAI systems by using ample documentation and techniques such as: application of gradient-based attributions, occlusion/term reduction, counterfactual prompts and prompt engineering, and analysis of embeddings; Assess and update risk measurement approaches at regular cadences | D32: NIST AI RMF: Generative AI Profile (NIST, 2024) | E32: 1.2 Gestão de riscos | F32: Angelo Andrioli Netho | G32: Sim | H32: Sim | I32: Sim | J32: Sim | K32: A0529 | L32: =IF(COUNTA(G32:J32)<4,"",IF(AND(G32="Sim",H32="Sim",I32="Sim",J32="Sim",K32=""),"Sim","Não")) -> Não | O32: Sim | Q32: Sim | R32: Sim | S32: Sim | T32: Sim | U32: Sim | V32: Aplicável a quem implanta ou opera sistemas de IA; ação concreta e comprovável. | W32: A0529_NIST2024 ML Explanation Application (0,23)
A33: A0419_NIST2024 | B33: Standardized Measurement Protocols | C33: Establish policies, procedures, and processes detailing risk measurement in context of use with standardized measurement protocols and structured public feedback exercises such as AI red-teaming or independent external evaluations. | D33: NIST AI RMF: Generative AI Profile (NIST, 2024) | E33: 3.1 Testes e auditoria | F33: Angelo Andrioli Netho | G33: Sim | H33: Sim | I33: Sim | J33: Sim | K33: A0490; A0493; | L33: =IF(COUNTA(G33:J33)<4,"",IF(AND(G33="Sim",H33="Sim",I33="Sim",J33="Sim",K33=""),"Sim","Não")) -> Não | O33: Sim | Q33: Sim | R33: Sim | S33: Sim | T33: Sim | U33: Sim | V33: Aplicável a quem implanta ou opera sistemas de IA; ação concreta e comprovável. | W33: A0490_NIST2024 Feedback Exercise Use Cases (0,16); A0493_NIST2024 External Evaluation Engagement (0,16)
A34: A0420_NIST2024 | B34: Lifecycle Oversight Functions | C34: Establish policies, procedures, and processes for oversight functions (e.g., senior leadership, legal, compliance, including internal evaluation) across the GAI lifecycle, from problem formulation and supply chains to system decommission. | D34: NIST AI RMF: Generative AI Profile (NIST, 2024) | E34: 1.1 Estrutura de conselho e supervisão | F34: Angelo Andrioli Netho | G34: Sim | H34: Sim | I34: Sim | J34: Sim | L34: =IF(COUNTA(G34:J34)<4,"",IF(AND(G34="Sim",H34="Sim",I34="Sim",J34="Sim",K34=""),"Sim","Não")) -> Sim | O34: Sim | Q34: Sim | R34: Sim | S34: Sim | T34: Sim | U34: Sim | V34: Aplicável a quem implanta ou opera sistemas de IA; ação concreta e comprovável.
A35: A0421_NIST2024 | B35: Terms of Service Establishment | C35: Establish terms of use and terms of service for GAI systems. | D35: NIST AI RMF: Generative AI Profile (NIST, 2024) | E35: 3.3 Gestão de acesso | F35: Angelo Andrioli Netho | G35: Sim | H35: Sim | I35: Sim | J35: Sim | K35: A0817 | L35: =IF(COUNTA(G35:J35)<4,"",IF(AND(G35="Sim",H35="Sim",I35="Sim",J35="Sim",K35=""),"Sim","Não")) -> Não | O35: Sim | Q35: Sim | R35: Sim | S35: Sim | T35: Sim | U35: Sim | V35: Aplicável a quem implanta ou opera sistemas de IA; ação concreta e comprovável. | W35: A0817_UK Government2023 Information Sharing with Downstream Users (0,17)
A36: A0422_NIST2024 | B36: Actor Inclusion in Risk ID | C36: Include relevant AI Actors in the GAI system risk identification process. | D36: NIST AI RMF: Generative AI Profile (NIST, 2024) | E36: 1.7 Avaliação de impacto social | F36: Angelo Andrioli Netho | G36: Sim | H36: Sim | I36: Sim | J36: Sim | L36: =IF(COUNTA(G36:J36)<4,"",IF(AND(G36="Sim",H36="Sim",I36="Sim",J36="Sim",K36=""),"Sim","Não")) -> Sim | O36: Sim | Q36: Sim | R36: Sim | S36: Sim | T36: Sim | U36: Sim | V36: Aplicável a quem implanta ou opera sistemas de IA; ação concreta e comprovável.
A37: A0423_NIST2024 | B37: Downstream Impact Verification | C37: Verify that downstream GAI system impacts (such as the use of third-party plugins) are included in the impact documentation process. | D37: NIST AI RMF: Generative AI Profile (NIST, 2024) | E37: 4.1 Documentação do sistema | F37: Angelo Andrioli Netho | G37: Sim | H37: Sim | I37: Sim | J37: Sim | L37: =IF(COUNTA(G37:J37)<4,"",IF(AND(G37="Sim",H37="Sim",I37="Sim",J37="Sim",K37=""),"Sim","Não")) -> Sim | O37: Sim | Q37: Sim | R37: Sim | S37: Sim | T37: Sim | U37: Sim | V37: Aplicável a quem implanta ou opera sistemas de IA; ação concreta e comprovável.
A38: A0424_NIST2024 | B38: Provenance Method Measurement | C38: Establish policies for measuring the effectiveness of employed content provenance methodologies (e.g., cryptography, watermarking, steganography, etc.) | D38: NIST AI RMF: Generative AI Profile (NIST, 2024) | E38: 2.4 Controles de segurança de conteúdo | F38: Angelo Andrioli Netho | G38: Sim | H38: Sim | I38: Sim | J38: Sim | L38: =IF(COUNTA(G38:J38)<4,"",IF(AND(G38="Sim",H38="Sim",I38="Sim",J38="Sim",K38=""),"Sim","Não")) -> Sim | O38: Sim | Q38: Sim | R38: Sim | S38: Sim | T38: Sim | U38: Sim | V38: Aplicável a quem implanta ou opera sistemas de IA; ação concreta e comprovável.
A39: A0425_NIST2024 | B39: Feedback Resource Allocation | C39: Allocate time and resources for outreach, feedback, and recourse processes in GAI system development. | D39: NIST AI RMF: Generative AI Profile (NIST, 2024) | E39: 4.3 Relato de incidentes | F39: Angelo Andrioli Netho | G39: Sim | H39: Não | I39: Sim | J39: Sim | L39: =IF(COUNTA(G39:J39)<4,"",IF(AND(G39="Sim",H39="Sim",I39="Sim",J39="Sim",K39=""),"Sim","Não")) -> Não | O39: Sim | Q39: Sim | R39: Sim | S39: Sim | T39: Sim | U39: Sim | V39: Aplicável a quem implanta ou opera sistemas de IA; ação concreta e comprovável.
A40: A0426_NIST2024 | B40: User Interaction Documentation | C40: Document interactions with GAI systems to users prior to interactive activities, particularly in contexts involving more significant risks. | D40: NIST AI RMF: Generative AI Profile (NIST, 2024) | E40: 4.6 Direitos e recursos dos usuários | F40: Angelo Andrioli Netho | G40: Sim | H40: Sim | I40: Sim | J40: Sim | K40: A0160 | L40: =IF(COUNTA(G40:J40)<4,"",IF(AND(G40="Sim",H40="Sim",I40="Sim",J40="Sim",K40=""),"Sim","Não")) -> Não | O40: Sim | Q40: Sim | R40: Sim | S40: Sim | T40: Sim | U40: Sim | V40: Aplicável a quem implanta ou opera sistemas de IA; ação concreta e comprovável. | W40: A0160_Future of Life Institute2024 User Interaction Monitoring & Response Restri (0,19)
...

Sheet Catálogo
A1: Nº | B1: Responsável | C1: ID na base | D1: Nome original | E1: Nome em português | F1: Documento de origem | G1: Subcategoria (Saeri) | H1: Descrição em português | I1: Subdomínios: anotador A | J1: Anotador A | K1: Subdomínios: anotador B | L1: Anotador B | M1: Concordância exata | N1: Subdomínios: consenso | O1: Risco-alvo sugerido | P1: Evidência esperada | Q1: Custo sugerido | R1: Evidência da estimativa | S1: Concordância das fontes | T1: Incerteza | U1: Fonte da estimativa | V1: Situação | W1: Observações | X1: Chave do documento | Y1: Código da subcategoria
A2: 1 | B2: Renato Pestana de Gouveia | C2: A0657_Barrett2024 | D2: Elicit Requirements & Assess Impacts | E2: Levantar requisitos e avaliar impactos | F2: AI Risk Management Standards Profile for GPAIS (Barrett et al., 2024) | G2: 1.2 Gestão de riscos | H2: Os requisitos do sistema (por exemplo, “o sistema deve respeitar a privacidade de seus usuários”) são levantados junto aos atores relevantes no contexto de IA e compreendidos por eles. As decisões de projeto levam em consideração as implicações sociotécnicas, visando tratar os riscos associados à IA. | I2: 1.1, 2.1, 6.5, 7.3, 7.4 | J2: Renato Pestana de Gouveia | K2: 1.1, 2.1, 4.1, 6.5, 7.3, 7.4 | L2: Fernando Alonso Piroga da Silva | M2: =IF(OR(I2="",K2=""),"",IF(TRIM(I2)=TRIM(K2),"Sim","Não")) -> Não | N2: 1.1, 2.1, 4.1, 6.5, 7.3, 7.4 | O2: Implementação de IA com decisões de projeto desalinhadas do contexto sociotécnico, gerando violações de direitos e falhas não previstas de governança. | P2: Documento de requisitos sociotécnicos aprovado pelas partes interessadas e matriz de rastreabilidade comprovando a incorporação desses requisitos na arquitetura/projeto do sistema. | Q2: Médio | R2: Média | S2: Alta | T2: =IF(OR(R2="",S2=""),"",CHOOSE(MATCH(R2,Listas!$X$5:$X$7,0)+MATCH(S2,Listas!$Z$5:$Z$7,0)-1,"Alta","Alta","Média","Baixa","Baixa")) -> Baixa | U2: Barrett et al. (2024, p. 33), perfil construído sobre o NIST AI RMF 1.0 (subcategoria MAP 1.6), descreve a ação e lista itens de ação e de documentação do Playbook do NIST, como avaliar impactos ao longo do ciclo de vida com especialistas e comunidades afetadas. De forma independente, a ISO/IEC 42001:2023 exige especificar e documentar os requisitos dos sistemas de IA (controle A.6.2.2) e avaliar e documentar os impactos sobre indivíduos, grupos e a sociedade (cláusulas 6.1.4 e 8.4; controles A.5). Custo estimado pelo grupo, pela rubrica. | V2: Concluída | X2: {=IFERROR(INDEX(Listas!$D$5:$D$17,MATCH(F2,Listas!$C$5:$C$17,0)),"")} -> barrett-2024 | Y2: =IFERROR(LEFT(G2,FIND(" ",G2)-1),"") -> 1.2
A3: 2 | B3: Renato Pestana de Gouveia | C3: A0675_Barrett2024 | D3: Measure & Document Deployment Performance | E3: Medir e documentar o desempenho da implantação | F3: AI Risk Management Standards Profile for GPAIS (Barrett et al., 2024) | G3: 4.1 Documentação do sistema | H3: Os critérios de desempenho ou de garantia de sistemas de IA são medidos de forma qualitativa ou quantitativa e demonstrados para condições semelhantes às do(s) ambiente(s) de implantação. As medições são documentadas. | I3: 6.5, 7.3, 7.4 | J3: Renato Pestana de Gouveia | K3: 4.1, 6.5, 7.3, 7.4 | L3: Fernando Alonso Piroga da Silva | M3: =IF(OR(I3="",K3=""),"",IF(TRIM(I3)=TRIM(K3),"Sim","Não")) -> Não | N3: 4.1, 6.5, 7.3, 7.4 | O3: Implantação de IA sem validação técnica prévia sob condições realistas de produção, resultando em falhas, comportamento impreciso e falta de rastreabilidade do desempenho | P3: Relatórios formais de testes de validação e garantia de qualidade (benchmarks/métricas quantitativas e qualificações qualitativas) documentando o comportamento do sistema em ambiente simulado ou pré-produtivo idêntico ao de implantação, contendo a aprovação da equipe técnica responsável. | Q3: Médio | R3: Média | S3: Alta | T3: =IF(OR(R3="",S3=""),"",CHOOSE(MATCH(R3,Listas!$X$5:$X$7,0)+MATCH(S3,Listas!$Z$5:$Z$7,0)-1,"Alta","Alta","Média","Baixa","Baixa")) -> Baixa | U3: Barrett et al. (2023, p. 46), perfil construído sobre o NIST AI RMF 1.0 (subcategoria MEASURE 2.5: "The AI system to be deployed is demonstrated to be valid and reliable. Limitations of the generalizability beyond the conditions under which the technology was developed are documented"), orienta a medição formal das formas de validade (incluindo validade externa/generalizabilidade), confiabilidade e robustez, além de documentar as limitações operacionais fora da distribuição de treino. De forma complementar e independente, a norma ISO/IEC 42001:2023 exige definir e documentar medidas de verificação e validação do sistema de IA (controle A.6.2.4 e seção B.6.2.4), incluindo critérios de aceitação, avaliação de robustez e tratamento das limitações de desempenho. Custo estimado pelo grupo, pela rubrica. | V3: Concluída | X3: {=IFERROR(INDEX(Listas!$D$5:$D$17,MATCH(F3,Listas!$C$5:$C$17,0)),"")} -> barrett-2024 | Y3: =IFERROR(LEFT(G3,FIND(" ",G3)-1),"") -> 4.1
A4: 3 | B4: Renato Pestana de Gouveia | C4: A0677_Barrett2024 | D4: Demonstrate Validity & Generalization Limits | E4: Demonstrar a validade e os limites de generalização | F4: AI Risk Management Standards Profile for GPAIS (Barrett et al., 2024) | G4: 3.1 Testes e auditoria | H4: O sistema de IA a ser implementado demonstra ser válido e confiável. As limitações quanto à sua generalizabilidade para além das condições em que a tecnologia foi desenvolvida estão documentadas. | I4: 6.5, 7.3, 7.4 | J4: Renato Pestana de Gouveia | K4: 4.1, 6.5, 7.3, 7.4 | L4: Fernando Alonso Piroga da Silva | M4: =IF(OR(I4="",K4=""),"",IF(TRIM(I4)=TRIM(K4),"Sim","Não")) -> Não | N4: 4.1, 6.5, 7.3, 7.4 | O4: Falhas imprevisíveis, alucinações ou perda severa de desempenho e confiabilidade ao operar fora das condições específicas de treinamento/desenvolvimento, resultando em tomada de decisão incorreta em cenários reais decorrente da falta de mapeamento formal dos limites de generalização e validade do modelo. | P4: Relatórios formais de avaliação e documentação de limites operacionais, contendo resultados de testes de validade (construto, interna e externa/generalizabilidade), métricas de robustez e confiabilidade sob diferentes condições de entrada, e especificação clara de casos de uso/domínios não recomendados no System Card ou Model Card. | Q4: Médio | R4: Média | S4: Alta | T4: =IF(OR(R4="",S4=""),"",CHOOSE(MATCH(R4,Listas!$X$5:$X$7,0)+MATCH(S4,Listas!$Z$5:$Z$7,0)-1,"Alta","Alta","Média","Baixa","Baixa")) -> Baixa | U4: Barrett et al. (2023, p. 46), perfil construído sobre o NIST AI RMF 1.0 (subcategoria MEASURE 2.5: "The AI system to be deployed is demonstrated to be valid and reliable. Limitations of the generalizability beyond the conditions under which the technology was developed are documented"), orienta a medição formal das formas de validade (incluindo validade externa/generalizabilidade), confiabilidade e robustez, além de documentar as limitações operacionais fora da distribuição de treino. De forma complementar e independente, a norma ISO/IEC 42001:2023 exige definir e documentar medidas de verificação e validação do sistema de IA (controle A.6.2.4 e seção B.6.2.4), incluindo critérios de aceitação, avaliação de robustez e tratamento das limitações de desempenho. Custo estimado pelo grupo, pela rubrica. | V4: Concluída | X4: {=IFERROR(INDEX(Listas!$D$5:$D$17,MATCH(F4,Listas!$C$5:$C$17,0)),"")} -> barrett-2024 | Y4: =IFERROR(LEFT(G4,FIND(" ",G4)-1),"") -> 3.1
A5: 4 | B5: Renato Pestana de Gouveia | C5: A0698_Barrett2024 | D5: Deactivate Misaligned Systems | E5: Desativar sistemas desalinhados | F5: AI Risk Management Standards Profile for GPAIS (Barrett et al., 2024) | G5: 3.6 Resposta a incidentes e recuperação | H5: Existem mecanismos implementados e em uso, bem como responsabilidades atribuídas e compreendidas, para substituir, desativar ou interromper sistemas de IA que apresentem desempenho ou resultados incompatíveis com o uso pretendido. | I5: 6.5, 7.3 | J5: Renato Pestana de Gouveia | K5: 6.5, 7.3 | L5: Fernando Alonso Piroga da Silva | M5: =IF(OR(I5="",K5=""),"",IF(TRIM(I5)=TRIM(K5),"Sim","Não")) -> Sim | N5: 6.5, 7.3 | O5: Uso continuado ou descontrole de sistemas de IA que apresentem comportamento desalinhado, indesejado ou de alto risco, resultando em falhas operacionais, ampliação de danos socioambientais, violação de diretrizes de governança ou incapacidade de interrupção emergencial (falta de mecanismos de kill switch / desligamento seguro). | P5: Procedimentos operacionais padronizados (SOPs) e protocolos técnicos documentados que estabeleçam limiares de acionamento para bypass, interrupção ou desativação emergencial de modelos (kill switches ou desligamento físico em centros de dados), acompanhados por matriz de responsabilidades e relatórios formais de testes do mecanismo de desativação executados em ambiente controlado. | Q5: Médio | R5: Média | S5: Alta | T5: =IF(OR(R5="",S5=""),"",CHOOSE(MATCH(R5,Listas!$X$5:$X$7,0)+MATCH(S5,Listas!$Z$5:$Z$7,0)-1,"Alta","Alta","Média","Baixa","Baixa")) -> Baixa | U5: Barrett et al. (2023, p. 59), perfil construído sobre o NIST AI RMF 1.0 (subcategoria MANAGE 2.4: "Mechanisms are in place and applied, and responsibilities are assigned and understood, to supersede, disengage, or deactivate AI systems that demonstrate performance or outcomes inconsistent with intended use"), orienta o planejamento de procedimentos de desligamento emergencial (emergency power off / kill switches), liberação gradual (staged-release) e acesso estruturado via API para garantir a capacidade de desativação. De forma independente e complementar, a norma ISO/IEC 42001:2023 prevê controles para tratamento e resposta a incidentes e interrupção operacional de sistemas de IA (cláusula 8.4 e anexos de controle A.8 e B.8). Custo estimado pelo grupo, pela rubrica. | V5: Concluída | X5: {=IFERROR(INDEX(Listas!$D$5:$D$17,MATCH(F5,Listas!$C$5:$C$17,0)),"")} -> barrett-2024 | Y5: =IFERROR(LEFT(G5,FIND(" ",G5)-1),"") -> 3.6
A6: 5 | B6: Renato Pestana de Gouveia | C6: A0699_Barrett2024 | D6: Monitor Third-Party Risks | E6: Monitorar riscos de terceiros | F6: AI Risk Management Standards Profile for GPAIS (Barrett et al., 2024) | G6: 1.2 Gestão de riscos | H6: Os riscos e benefícios da IA ​​provenientes de recursos de terceiros são monitorados regularmente, e controles de risco são aplicados e documentados. | I6: 2.2, 6.5, 7.3, 7.4 | J6: Renato Pestana de Gouveia | K6: 2.2, 6.5, 7.3, 7.4 | L6: Fernando Alonso Piroga da Silva | M6: =IF(OR(I6="",K6=""),"",IF(TRIM(I6)=TRIM(K6),"Sim","Não")) -> Sim | N6: 2.2, 6.5, 7.3, 7.4 | O6: Propagação de falhas, vulnerabilidades de segurança, viés ou violação de direitos oriundos de componentes de terceiros (datasets não curados, software/APIs, modelos pré-treinados ou infraestrutura em nuvem), resultando em contaminação de dados (data poisoning), perda de conformidade legal/IP ou dependência crítica de fornecedores sem controles adequados de governança. | P6: Política formal de gestão de riscos de fornecedores e cadeia de suprimentos de IA, contendo registros de due diligence, relatórios de auditoria/testes de segurança de componentes adquiridos, logs de monitoramento contínuo do desempenho e da confiabilidade das soluções de terceiros, e inventário atualizado de ativos externos com seus respectivos termos contratuais e planos de contingência. | Q6: Médio | R6: Média | S6: Alta | T6: =IF(OR(R6="",S6=""),"",CHOOSE(MATCH(R6,Listas!$X$5:$X$7,0)+MATCH(S6,Listas!$Z$5:$Z$7,0)-1,"Alta","Alta","Média","Baixa","Baixa")) -> Baixa | U6: Barrett et al. (2023, p. 28, 60), perfil construído sobre o NIST AI RMF 1.0 (subcategorias GOVERN 6.1/6.2 e MANAGE 3.1/3.2: "AI risks and benefits from third-party entities are managed"), orienta o monitoramento contínuo, verificação de transparência sobre dados de treino, avaliações contratuais e planos de contingência/desativação para fornecedores de software, dados ou modelos. De forma independente e complementar, a norma ISO/IEC 42001:2023 aborda a gestão de fornecedores e recursos externos de IA no controle A.9.3 (Management of third-party resources) e cláusulas de controle de cadeia de suprimentos. Custo estimado pelo grupo, pela rubrica. | V6: Concluída | X6: {=IFERROR(INDEX(Listas!$D$5:$D$17,MATCH(F6,Listas!$C$5:$C$17,0)),"")} -> barrett-2024 | Y6: =IFERROR(LEFT(G6,FIND(" ",G6)-1),"") -> 1.2
A7: 6 | B7: Renato Pestana de Gouveia | C7: A0701_Barrett2024 | D7: Implement Post-deployment Monitoring Plan | E7: Implementar plano de monitoramento pós-implantação | F7: AI Risk Management Standards Profile for GPAIS (Barrett et al., 2024) | G7: 3.5 Monitoramento pós-implantação | H7: São implementados planos de monitoramento de sistemas de IA após a sua implantação, incluindo mecanismos para a coleta e avaliação de contribuições de usuários e outros atores relevantes no contexto da IA, bem como procedimentos para recursos e reversão de decisões, desativação, resposta a incidentes, recuperação e gestão de mudanças. | I7: 5.2, 6.5, 7.3, 7.4 | J7: Renato Pestana de Gouveia | K7: 5.2, 6.5, 7.3, 7.4 | L7: Fernando Alonso Piroga da Silva | M7: =IF(OR(I7="",K7=""),"",IF(TRIM(I7)=TRIM(K7),"Sim","Não")) -> Sim | N7: 5.2, 6.5, 7.3, 7.4 | O7: Degradação não detectada do desempenho, surgimento de desvios (concept drift / data drift), comportamentos emergentes nocivos ou falhas de segurança pós-implantação, resultando em decisões incorretas do sistema, impactos não mitigados sobre usuários/comunidades afetadas e ausência de resposta tempestiva a incidentes ou canal de contestação. | P7: Plano formal de monitoramento pós-implantação operacionalizado, contendo painéis (dashboards) de métricas contínuas de desempenho/confiabilidade, registros de testes TEVV pós-implantação, histórico de relatórios de incidentes e near-misses integrados a bases de incidentes, bem como fluxos documentados de canais de feedback, contestação e gestão de mudanças (versioning). | Q7: Médio | R7: Média | S7: Alta | T7: =IF(OR(R7="",S7=""),"",CHOOSE(MATCH(R7,Listas!$X$5:$X$7,0)+MATCH(S7,Listas!$Z$5:$Z$7,0)-1,"Alta","Alta","Média","Baixa","Baixa")) -> Baixa | U7: Barrett et al. (2023, p. 61), perfil construído sobre o NIST AI RMF 1.0 (subcategoria MANAGE 4.1: "Post-deployment AI system monitoring plans are implemented, including mechanisms for capturing and evaluating input from users and other relevant AI actors, appeal and override, system decommissioning, incident response, recovery, and change management"), orienta a realização de testes TEVV pós-implantação, rodadas periódicas de red-teaming, canais de feedback/recurso e compartilhamento de informações sobre erros/incidentes. De forma independente e complementar, a norma ISO/IEC 42001:2023 exige o monitoramento contínuo e a avaliação do sistema de IA em produção na cláusula 9.2/9.3 e no controle A.8.4 (AI system monitoring). Custo estimado pelo grupo, pela rubrica. | V7: Concluída | X7: {=IFERROR(INDEX(Listas!$D$5:$D$17,MATCH(F7,Listas!$C$5:$C$17,0)),"")} -> barrett-2024 | Y7: =IFERROR(LEFT(G7,FIND(" ",G7)-1),"") -> 3.5
A8: 7 | B8: Renato Pestana de Gouveia | C8: A0703_Barrett2024 | D8: Report & Respond to Incidents | E8: Relatar e responder a incidentes | F8: AI Risk Management Standards Profile for GPAIS (Barrett et al., 2024) | G8: 4.3 Relato de incidentes | H8: Incidentes e erros são comunicados aos atores de IA pertinentes, incluindo as comunidades afetadas. Processos para o acompanhamento, a resposta e a recuperação diante de incidentes e erros são seguidos e documentados. | I8: 1.1, 3.1, 6.5, 7.4 | J8: Renato Pestana de Gouveia | K8: 3.1, 6.5, 7.4 | L8: Fernando Alonso Piroga da Silva | M8: =IF(OR(I8="",K8=""),"",IF(TRIM(I8)=TRIM(K8),"Sim","Não")) -> Não | N8: 3.1, 6.5, 7.4 | O8: Atraso na identificação, falha na comunicação ou resposta inadequada a erros, violações ou incidentes causados pelo sistema de IA, resultando no agravamento de danos aos afetados, perda de rastreabilidade, descumprimento de obrigações regulatórias de notificação e reincidência de falhas evitáveis. | P8: Plano de resposta e recuperação a incidentes de IA documentado, acompanhado de um banco de dados/registro ativo de incidentes e near-misses (contendo data, severidade, impacto e ações corretivas), relatórios formais de notificação enviados às partes interessadas e comunidades afetadas, e comprovação de submissão a repositórios públicos de incidentes (como o AI Incident Database - AIID). | Q8: Médio | R8: Média | S8: Alta | T8: =IF(OR(R8="",S8=""),"",CHOOSE(MATCH(R8,Listas!$X$5:$X$7,0)+MATCH(S8,Listas!$Z$5:$Z$7,0)-1,"Alta","Alta","Média","Baixa","Baixa")) -> Baixa | U8: Barrett et al. (2023, p. 62), perfil construído sobre o NIST AI RMF 1.0 (subcategoria MANAGE 4.3: "Incidents and errors are communicated to relevant AI actors, including affected communities. Processes for tracking, responding to, and recovering from incidents and errors are followed and documented"), orienta a manutenção de banco de dados de erros/incidentes, procedimentos de notificação contínua e compartilhamento público de dados de falhas. De forma independente e complementar, a norma ISO/IEC 42001:2023 exige a gestão, tratamento e relato de incidentes de sistemas de IA (cláusula 10.1/10.2 e controles de resposta a incidentes A.8.5). Custo estimado pelo grupo, pela rubrica. | V8: Concluída | X8: {=IFERROR(INDEX(Listas!$D$5:$D$17,MATCH(F8,Listas!$C$5:$C$17,0)),"")} -> barrett-2024 | Y8: =IFERROR(LEFT(G8,FIND(" ",G8)-1),"") -> 4.3
A9: 8 | B9: Renato Pestana de Gouveia | C9: A0069_Eisenberg2025 | D9: Establish user rights and recourse framework | E9: Estabelecer direitos dos usuários e um mecanismo de recurso | F9: The Unified Control Framework (Eisenberg et al., 2025) | G9: 4.6 Direitos e recursos dos usuários | H9: Implemente mecanismos abrangentes para o relato por parte dos usuários, coleta de feedback, investigação de incidentes e disponibilização de recursos, incluindo procedimentos claros para que os usuários possam relatar problemas, solicitar explicações ou correções, recorrer de decisões e obter a devida reparação. O sistema deve ser capaz de lidar com diversos tipos de preocupações dos usuários, incluindo erros no sistema, tratamento injusto, violações de privacidade e questões de segurança. | I9: 1.1, 2.1, 2.2, 5.2, 6.5, 7.3, 7.4 | J9: Renato Pestana de Gouveia | K9: 1.1, 2.1, 2.2, 5.2, 6.5, 7.3, 7.4 | L9: Fernando Alonso Piroga da Silva | M9: =IF(OR(I9="",K9=""),"",IF(TRIM(I9)=TRIM(K9),"Sim","Não")) -> Sim | N9: 1.1, 2.1, 2.2, 5.2, 6.5, 7.3, 7.4 | O9: Incapacidade de contestação ou contestação de decisões automatizadas adversas ou de alto impacto impostas aos usuários, culminando na violação de direitos individuais (privacidade, equidade e devido processo), perpetuação de discriminação algorítmica/tratamento injusto e ocorrência de danos morais ou materiais sem mecanismo de recurso (recourse), correção ou reparação adequada. | P9: Mecanismo operacional de direitos e recurso dos usuários documentado e funcional, composto por procedimentos formais de triagem e investigação de incidentes, canal público/acessível para solicitação de explicações e contestação de decisões, protocolo de revisão humana de decisões contestadas e registros de auditoria (logs de solicitações, tempo de resposta e reparações/correções efetuadas). | Q9: Médio | R9: Média | S9: Alta | T9: =IF(OR(R9="",S9=""),"",CHOOSE(MATCH(R9,Listas!$X$5:$X$7,0)+MATCH(S9,Listas!$Z$5:$Z$7,0)-1,"Alta","Alta","Média","Baixa","Baixa")) -> Baixa | U9: Eisenberg et al. (2025, p. 29, 31), no The Unified Control Framework (UCF), define o Control-028 (Establish user rights and recourse framework), exigindo rotinas para coleta de feedback, investigação de incidentes, explicação e contestação de decisões adversas em conformidade com o Colorado AI Act (Seção 6-1-1703.4). De forma independente e complementar, a ISO/IEC 42001:2023 prevê mecanismos de gestão de reclamações de partes interessadas, transparência e avaliação de impactos no controle A.5.4 (Stakeholder feedback and reporting mechanisms). Custo estimado pelo grupo, pela rubrica. | V9: Concluída | X9: {=IFERROR(INDEX(Listas!$D$5:$D$17,MATCH(F9,Listas!$C$5:$C$17,0)),"")} -> eisenberg-2025 | Y9: =IFERROR(LEFT(G9,FIND(" ",G9)-1),"") -> 4.6
A10: 9 | B10: Renato Pestana de Gouveia | C10: A0074_Eisenberg2025 | D10: Establish third-party assessment and management framework | E10: Estabelecer uma estrutura de avaliação e gestão de terceiros | F10: The Unified Control Framework (Eisenberg et al., 2025) | G10: 4.5 Acesso de terceiros ao sistema | H10: Estabeleça procedimentos abrangentes para documentar, avaliar e gerenciar fornecedores e dependências a montante na cadeia de valor de sistemas de IA, incluindo requisitos de transparência, verificação de conformidade, rastreamento de dependências e planejamento de contingência. | I10: 2.2, 6.5, 7.3, 7.4 | J10: Renato Pestana de Gouveia | K10: 2.2, 6.5, 7.3, 7.4 | L10: Fernando Alonso Piroga da Silva | M10: =IF(OR(I10="",K10=""),"",IF(TRIM(I10)=TRIM(K10),"Sim","Não")) -> Sim | N10: 2.2, 6.5, 7.3, 7.4 | O10: Propagação de falhas, vulnerabilidades de segurança, opacidade técnica ou descumprimento regulatório originados de componentes, fornecedores ou modelos a montante (upstream) na cadeia de valor de IA, resultando em dependência não gerenciada de terceiros (vendor lock-in), interrupções operacionais e perda de controle sobre a conformidade e integridade do sistema. | P10: Estrutura formal de avaliação e gestão de riscos de fornecedores/terceiros implementada, contendo relatórios de due diligence e auditoria de fornecedores, inventário atualizado de dependências a montante (software, modelos pré-treinados, APIs e dados), requisitos contratuais de transparência/conformidade documentados e planos de contingência/alternativas operacionais para falhas de terceiros. | Q10: Médio | R10: Média | S10: Alta | T10: =IF(OR(R10="",S10=""),"",CHOOSE(MATCH(R10,Listas!$X$5:$X$7,0)+MATCH(S10,Listas!$Z$5:$Z$7,0)-1,"Alta","Alta","Média","Baixa","Baixa")) -> Baixa | U10: Eisenberg et al. (2025, p. 30), no The Unified Control Framework (UCF), define o Control-033 (Establish third-party assessment and management framework), estabelecendo procedimentos para documentação, avaliação de conformidade, rastreamento de dependências e plano de contingência para fornecedores na cadeia de valor de IA. De forma independente e complementar, a norma ISO/IEC 42001:2023 aborda a gestão de recursos de terceiros e cadeia de suprimentos de IA nos controles A.9.3 (Management of third-party resources) e cláusulas associadas. Custo estimado pelo grupo, pela rubrica. | V10: Concluída | X10: {=IFERROR(INDEX(Listas!$D$5:$D$17,MATCH(F10,Listas!$C$5:$C$17,0)),"")} -> eisenberg-2025 | Y10: =IFERROR(LEFT(G10,FIND(" ",G10)-1),"") -> 4.5
