Workbook

Sheet Leia-me
A1: Formulário de avaliação do Framework RME por painel de especialistas
A2: Anexo do projeto. Instrumento do painel Delphi do OE6, elaborado conforme a decisão 0027 e o protocolo do painel (docs/expert-panel-protocol.md). O painel não foi executado neste trabalho; o instrumento fica pronto para execução futura.
A4: Abas
A5: Termo | B5: Apresentação da pesquisa, termo de consentimento e identificação do especialista. Preenchida uma vez, antes da primeira rodada.
A6: Rodada 1 | B6: Refinamento: clareza da redação de cada item, intervalos de revisão sugeridos e elementos ausentes.
A7: Rodada 2 | B7: Avaliação: escala de Lawshe (1975) para cada item e nova coleta dos intervalos, com o resumo da primeira rodada como retorno.
A8: Consolidação | B8: Uso da coordenação. Uma linha por especialista com as respostas da segunda rodada, no formato lido pelo comando expert-panel:cvr. Exportar esta aba como CSV.
A9: Análise | B9: Uso da coordenação. Conferência do CVR, do valor crítico, dos critérios do OE3 e do OE6 e dos intervalos, calculada a partir da aba Consolidação. O resultado oficial é o do comando expert-panel:cvr.
A10: Legenda
A11: Células amarelas | B11: Campos a preencher. Nas colunas com lista, escolha uma das opções.
A12: Demais células | B12: Texto fixo do instrumento ou fórmulas; não alterar.
A13: Fluxo
A14: 1 | B14: Enviar ao especialista as abas Termo e Rodada 1, com o material de apoio (síntese, glossário e vídeo do protótipo).
A15: 2 | B15: Consolidar a primeira rodada conforme a Seção 5.2 do protocolo: ajustar a redação dos itens, registrar as alterações e calcular a mediana e os quartis dos intervalos.
A16: 3 | B16: Preencher, na aba Rodada 2, o resumo da primeira rodada e enviá-la apenas a quem respondeu à primeira.
A17: 4 | B17: Transcrever as respostas da segunda rodada para a aba Consolidação, uma linha por especialista, identificado só pelo código.
A18: 5 | B18: Exportar a aba Consolidação como CSV (round-2-responses.csv) e rodar php artisan expert-panel:cvr.
A19: Exemplo de linha | B19: Na aba Consolidação: Respondente = E01; cada coluna de item = Essencial, Útil, mas não essencial ou Desnecessário; [INT-ALTO] = 90; [INT-LIMITADO] = 180; [INT-MINIMO] = 365 (números inteiros de dias).

Sheet Termo
A1: Painel de especialistas do Framework RME
A3: Apresentação
A4: Este questionário integra a avaliação do Framework RME (Risco, Mitigação e Evidência), desenvolvido na disciplina de Pesquisa Aplicada da Pontifícia Universidade Católica do Paraná (PUCPR) por Angelo Andrioli Netho, Fernando Alonso Piroga da Silva, Hugo Fagundes Faria Santos e Renato Pestana de Gouveia, sob orientação de [nome do professor]. O framework apoia o acompanhamento de riscos de sistemas de IA, das mitigações adotadas e das evidências de sua eficácia, inclusive depois da implantação.
A6: Termo de consentimento livre e esclarecido
A7: Objetivo. A pesquisa avalia a validade de conteúdo e a utilidade percebida do framework por meio de um painel Delphi de especialistas.
A8: Participação. Consiste em duas rodadas deste questionário, de cerca de [tempo] minutos cada, com intervalo aproximado de uma semana. Na primeira, você avalia a clareza dos itens e sugere intervalos de revisão; na segunda, avalia cada item e recebe um resumo anônimo das respostas da primeira.
A9: Voluntariedade. A participação é voluntária e pode ser interrompida a qualquer momento, sem prejuízo e sem necessidade de justificativa.
A10: Sigilo. As respostas são identificadas apenas por um código e relatadas de forma agregada. Comentários eventualmente citados no trabalho não identificam o autor. Nome e contato ficam em lista separada, acessível somente aos pesquisadores.
A11: Guarda dos dados. Os dados são acessíveis somente aos pesquisadores e ao orientador e serão mantidos por [prazo]. Apenas as respostas anonimizadas integram o repositório público do projeto.
A12: Riscos e benefícios. Os riscos se limitam ao tempo dedicado às respostas. Não há benefício direto; a contribuição apoia o desenvolvimento de práticas de governança de IA.
A13: Contato. [e-mail do grupo]; orientador: [e-mail do orientador].
A15: Identificação
... A22: O código é atribuído pela coordenação no convite. Não informe o nome neste arquivo.

Sheet Rodada 1
A1: Rodada 1: refinamento
A2: Para cada item, indique se a redação é clara e, se quiser, sugira outra redação. Nesta rodada não se pergunta se o item é essencial: isso fica para a segunda rodada. Consulte o material de apoio (síntese, glossário e vídeo do protótipo).
A4: Código do especialista
A6: Item | B6: Enunciado | C6: A redação é clara? | D6: Sugestão de redação ou comentário (opcional)
A7: A. Modelo de vínculo (C1)
A8: MOD-1 | B8: Toda mitigação adotada em um sistema de IA é registrada como vínculo com um risco declarado desse sistema: não há mitigação adotada sem risco correspondente.
A9: MOD-2 | B9: Cada vínculo tem um responsável, identificado por um papel organizacional (cargo e área), e não por uma pessoa.
A10: MOD-3 | B10: O status do vínculo tem duas dimensões: o progresso da implementação e a verificação, que distingue a mitigação apenas declarada da comprovada por evidência.
A11: MOD-4 | B11: Um vínculo só passa a verificado mediante evidência registrada; depois de voltar à reavaliação, uma nova verificação exige evidência nova.
A12: MOD-5 | B12: O histórico de status e as evidências são somente de inclusão: registros anteriores não são editados nem apagados.
A13: B. Catálogo de mitigações (C2)
A14: CAT-1 | B14: As mitigações do catálogo são organizadas nas quatro categorias de Saeri et al. (2025): governança e supervisão; técnico e segurança; processos operacionais; transparência e responsabilização.
A15: CAT-2 | B15: Cada mitigação do catálogo indica os subdomínios de risco da taxonomia do MIT AI Risk Repository que ela reduz diretamente e a evidência esperada de sua aplicação.
A16: CAT-3 | B16: Cada mitigação do catálogo traz uma estimativa qualitativa de custo (baixo, médio ou alto) e o nível de incerteza dessa estimativa.
A17: C. Protocolo de monitoramento (C3)
A18: DEF-C1 | B18: A ocorrência é observada em um sistema de IA em operação, isto é, usado em decisão, interação ou processo real cujos efeitos alcançam pessoas ou bens reais, inclusive em piloto, implantação em etapas ou uso interno. Ocorrências em testes, avaliações ou exercícios controlados são resultados de teste.
A19: DEF-C2 | B19: A ocorrência decorre do funcionamento, do uso ou de falha do sistema, inclusive quando ele opera conforme projetado.
A20: DEF-C3a | B20: A ocorrência causou dano (incidente) ou poderia plausivelmente tê-lo causado (quase-incidente); ambos são eventos adversos.
A21: DEF-C3b | B21: O dano considerado pode recair sobre pessoas ou grupos, sobre a organização que opera o sistema ou sobre o ecossistema, incluindo o meio ambiente.
A22: DEF-C4 | B22: A ocorrência pode ser associada a ao menos um subdomínio da taxonomia de riscos adotada, haja ou não risco cadastrado nesse subdomínio.
A23: DEF-C5 | B23: Basta a suspeita fundamentada para registrar. A relação causal é apurada na reavaliação do vínculo.
A24: DEF-C6 | B24: Uma ocorrência barrada por mitigação antes de causar dano é registrada como quase-incidente, podendo indicar o vínculo que a interceptou.
A25: MON-1 | B25: O registro de um evento adverso devolve à reavaliação os vínculos verificados do sistema cujo risco está em algum dos subdomínios do evento.
A26: MON-2 | B26: O registro de uma mudança do sistema (nova versão do modelo ou alteração na base de dados) devolve à reavaliação os vínculos verificados dos subdomínios afetados, ou todos, quando os subdomínios afetados não são informados.
A27: MON-3 | B27: A verificação de cada vínculo vale por um prazo proporcional à faixa de risco do sistema no EU AI Act; vencido o prazo, o vínculo volta à reavaliação.
A28: D. Protótipo (C4)
A29: PRO-1 | B29: O protótipo exporta, por sistema de IA, um relatório de rastreabilidade que liga riscos, mitigações, responsáveis, evidências, histórico de status, reavaliações, eventos adversos e mudanças do sistema.
A30: PRO-2 | B30: A tela de acompanhamento do protótipo mostra os vínculos que aguardam reavaliação, separados pelo gatilho que os originou: vencimento, evento adverso, mudança do sistema, reclassificação ou decisão manual.
A31: PRO-3 | B31: O protótipo alerta quando um evento adverso ou uma mudança do sistema aponta um subdomínio de risco sem risco cadastrado para o sistema.
A33: Intervalos de revisão
A34: Na ausência de eventos adversos, em quantos dias uma mitigação já verificada deveria ser revista em um sistema de IA de cada faixa de risco do EU AI Act? Informe um número inteiro de dias.
A35: Faixa | B35: Descrição | C35: Intervalo (dias) | D35: Justificativa (opcional)
A36: Alto risco | B36: Sistemas de alto risco (EU AI Act, art. 6 e Anexo III).
A37: Risco limitado | B37: Sistemas sujeitos a obrigações de transparência.
A38: Risco mínimo | B38: Demais sistemas.
A40: Elementos ausentes
A41: Há algum elemento essencial ao acompanhamento de riscos de sistemas de IA que o framework não contempla? (opcional)

Sheet Rodada 2
A1: Rodada 2: avaliação
A2: Considerando o propósito do Framework RME, classifique cada elemento como Essencial, Útil, mas não essencial ou Desnecessário. Todas as respostas são obrigatórias.
A4: Código do especialista
A6: Resumo da rodada 1 (preenchido pela coordenação)
A7: Respondentes da rodada 1
A8: Itens com redação alterada (e motivo)
A10: Item | B10: Enunciado | C10: Este elemento é
A11: A. Modelo de vínculo (C1)
A12: MOD-1 | B12: Toda mitigação adotada em um sistema de IA é registrada como vínculo com um risco declarado desse sistema: não há mitigação adotada sem risco correspondente.
A13: MOD-2 | B13: Cada vínculo tem um responsável, identificado por um papel organizacional (cargo e área), e não por uma pessoa.
A14: MOD-3 | B14: O status do vínculo tem duas dimensões: o progresso da implementação e a verificação, que distingue a mitigação apenas declarada da comprovada por evidência.
A15: MOD-4 | B15: Um vínculo só passa a verificado mediante evidência registrada; depois de voltar à reavaliação, uma nova verificação exige evidência nova.
A16: MOD-5 | B16: O histórico de status e as evidências são somente de inclusão: registros anteriores não são editados nem apagados.
A17: B. Catálogo de mitigações (C2)
A18: CAT-1 | B18: As mitigações do catálogo são organizadas nas quatro categorias de Saeri et al. (2025): governança e supervisão; técnico e segurança; processos operacionais; transparência e responsabilização.
A19: CAT-2 | B19: Cada mitigação do catálogo indica os subdomínios de risco da taxonomia do MIT AI Risk Repository que ela reduz diretamente e a evidência esperada de sua aplicação.
A20: CAT-3 | B20: Cada mitigação do catálogo traz uma estimativa qualitativa de custo (baixo, médio ou alto) e o nível de incerteza dessa estimativa.
A21: C. Protocolo de monitoramento (C3)
A22: DEF-C1 | B22: A ocorrência é observada em um sistema de IA em operação, isto é, usado em decisão, interação ou processo real cujos efeitos alcançam pessoas ou bens reais, inclusive em piloto, implantação em etapas ou uso interno. Ocorrências em testes, avaliações ou exercícios controlados são resultados de teste.
A23: DEF-C2 | B23: A ocorrência decorre do funcionamento, do uso ou de falha do sistema, inclusive quando ele opera conforme projetado.
A24: DEF-C3a | B24: A ocorrência causou dano (incidente) ou poderia plausivelmente tê-lo causado (quase-incidente); ambos são eventos adversos.
A25: DEF-C3b | B25: O dano considerado pode recair sobre pessoas ou grupos, sobre a organização que opera o sistema ou sobre o ecossistema, incluindo o meio ambiente.
A26: DEF-C4 | B26: A ocorrência pode ser associada a ao menos um subdomínio da taxonomia de riscos adotada, haja ou não risco cadastrado nesse subdomínio.
A27: DEF-C5 | B27: Basta a suspeita fundamentada para registrar. A relação causal é apurada na reavaliação do vínculo.
A28: DEF-C6 | B28: Uma ocorrência barrada por mitigação antes de causar dano é registrada como quase-incidente, podendo indicar o vínculo que a interceptou.
A29: MON-1 | B29: O registro de um evento adverso devolve à reavaliação os vínculos verificados do sistema cujo risco está em algum dos subdomínios do evento.
A30: MON-2 | B30: O registro de uma mudança do sistema (nova versão do modelo ou alteração na base de dados) devolve à reavaliação os vínculos verificados dos subdomínios afetados, ou todos, quando os subdomínios afetados não são informados.
A31: MON-3 | B31: A verificação de cada vínculo vale por um prazo proporcional à faixa de risco do sistema no EU AI Act; vencido o prazo, o vínculo volta à reavaliação.
A32: D. Protótipo (C4)
A33: PRO-1 | B33: O protótipo exporta, por sistema de IA, um relatório de rastreabilidade que liga riscos, mitigações, responsáveis, evidências, histórico de status, reavaliações, eventos adversos e mudanças do sistema.
A34: PRO-2 | B34: A tela de acompanhamento do protótipo mostra os vínculos que aguardam reavaliação, separados pelo gatilho que os originou: vencimento, evento adverso, mudança do sistema, reclassificação ou decisão manual.
A35: PRO-3 | B35: O protótipo alerta quando um evento adverso ou uma mudança do sistema aponta um subdomínio de risco sem risco cadastrado para o sistema.
A37: Intervalos de revisão
A38: A mesma pergunta da rodada 1, agora com a mediana e os quartis das respostas como referência. Informe novamente o intervalo, em dias, que considera adequado.
A39: Faixa | B39: Rodada 1: mediana (1º a 3º quartil) | C39: Seu intervalo (dias)
A40: Alto risco
A41: Risco limitado
A42: Risco mínimo
A44: Comentários gerais (opcional)

Sheet Consolidação
A1: Respondente | B1: [MOD-1] | C1: [MOD-2] | D1: [MOD-3] | E1: [MOD-4] | F1: [MOD-5] | G1: [CAT-1] | H1: [CAT-2] | I1: [CAT-3] | J1: [DEF-C1] | K1: [DEF-C2] | L1: [DEF-C3a] | M1: [DEF-C3b] | N1: [DEF-C4] | O1: [DEF-C5] | P1: [DEF-C6] | Q1: [MON-1] | R1: [MON-2] | S1: [MON-3] | T1: [PRO-1] | U1: [PRO-2] | V1: [PRO-3] | W1: [INT-ALTO] | X1: [INT-LIMITADO] | Y1: [INT-MINIMO]

Sheet Análise
A1: Análise da rodada 2 (conferência)
A2: Calculada a partir da aba Consolidação. Conferência do resultado; o resultado oficial, relatado no trabalho, é o gerado pelo comando expert-panel:cvr (decisão 0027).
A4: Respondentes (N) | C4: =COUNTA('Consolidação'!$A$2:$A$61) -> 0
A5: nₑ crítico | C5: =IF(AND($C$4>=5,$C$4<=60),CRITBINOM($C$4,0.5,0.95)+1,"-") -> - | D5: Menor nₑ com P(X ≥ nₑ) < 0,05, X ~ Binomial(N; 0,5), unilateral (Ayre e Scally, 2014). Exige N entre 5 e 60.
A6: CVR crítico | C6: =IF(ISNUMBER($C$5),(2*$C$5-$C$4)/$C$4,"-") -> -
A8: Item | B8: Bloco | C8: Objetivo | D8: Essencial | E8: Útil | F8: Desnecessário | G8: CVR | H8: Mantido | I8: Enunciado
A9: MOD-1 | B9: A. Modelo de vínculo (C1) | C9: OE6 | D9: =COUNTIF('Consolidação'!$B$2:$B$61,"Essencial") -> 0 | E9: =COUNTIF('Consolidação'!$B$2:$B$61,"Útil, mas não essencial") -> 0 | F9: =COUNTIF('Consolidação'!$B$2:$B$61,"Desnecessário") -> 0 | G9: =IF(ISNUMBER($C$5),(D9-$C$4/2)/($C$4/2),"-") -> - | H9: =IF(ISNUMBER($C$5),IF(D9>=$C$5,"sim","não"),"-") -> - | I9: Toda mitigação adotada em um sistema de IA é registrada como vínculo com um risco declarado desse sistema: não há mitigação adotada sem risco correspondente.
A10: MOD-2 | B10: A. Modelo de vínculo (C1) | C10: OE6 | D10: =COUNTIF('Consolidação'!$C$2:$C$61,"Essencial") -> 0 | E10: =COUNTIF('Consolidação'!$C$2:$C$61,"Útil, mas não essencial") -> 0 | F10: =COUNTIF('Consolidação'!$C$2:$C$61,"Desnecessário") -> 0 | G10: =IF(ISNUMBER($C$5),(D10-$C$4/2)/($C$4/2),"-") -> - | H10: =IF(ISNUMBER($C$5),IF(D10>=$C$5,"sim","não"),"-") -> - | I10: Cada vínculo tem um responsável, identificado por um papel organizacional (cargo e área), e não por uma pessoa.
A11: MOD-3 | B11: A. Modelo de vínculo (C1) | C11: OE6 | D11: =COUNTIF('Consolidação'!$D$2:$D$61,"Essencial") -> 0 | E11: =COUNTIF('Consolidação'!$D$2:$D$61,"Útil, mas não essencial") -> 0 | F11: =COUNTIF('Consolidação'!$D$2:$D$61,"Desnecessário") -> 0 | G11: =IF(ISNUMBER($C$5),(D11-$C$4/2)/($C$4/2),"-") -> - | H11: =IF(ISNUMBER($C$5),IF(D11>=$C$5,"sim","não"),"-") -> - | I11: O status do vínculo tem duas dimensões: o progresso da implementação e a verificação, que distingue a mitigação apenas declarada da comprovada por evidência.
A12: MOD-4 | B12: A. Modelo de vínculo (C1) | C12: OE6 | D12: =COUNTIF('Consolidação'!$E$2:$E$61,"Essencial") -> 0 | E12: =COUNTIF('Consolidação'!$E$2:$E$61,"Útil, mas não essencial") -> 0 | F12: =COUNTIF('Consolidação'!$E$2:$E$61,"Desnecessário") -> 0 | G12: =IF(ISNUMBER($C$5),(D12-$C$4/2)/($C$4/2),"-") -> - | H12: =IF(ISNUMBER($C$5),IF(D12>=$C$5,"sim","não"),"-") -> - | I12: Um vínculo só passa a verificado mediante evidência registrada; depois de voltar à reavaliação, uma nova verificação exige evidência nova.
A13: MOD-5 | B13: A. Modelo de vínculo (C1) | C13: OE6 | D13: =COUNTIF('Consolidação'!$F$2:$F$61,"Essencial") -> 0 | E13: =COUNTIF('Consolidação'!$F$2:$F$61,"Útil, mas não essencial") -> 0 | F13: =COUNTIF('Consolidação'!$F$2:$F$61,"Desnecessário") -> 0 | G13: =IF(ISNUMBER($C$5),(D13-$C$4/2)/($C$4/2),"-") -> - | H13: =IF(ISNUMBER($C$5),IF(D13>=$C$5,"sim","não"),"-") -> - | I13: O histórico de status e as evidências são somente de inclusão: registros anteriores não são editados nem apagados.
A14: CAT-1 | B14: B. Catálogo de mitigações (C2) | C14: OE6 | D14: =COUNTIF('Consolidação'!$G$2:$G$61,"Essencial") -> 0 | E14: =COUNTIF('Consolidação'!$G$2:$G$61,"Útil, mas não essencial") -> 0 | F14: =COUNTIF('Consolidação'!$G$2:$G$61,"Desnecessário") -> 0 | G14: =IF(ISNUMBER($C$5),(D14-$C$4/2)/($C$4/2),"-") -> - | H14: =IF(ISNUMBER($C$5),IF(D14>=$C$5,"sim","não"),"-") -> - | I14: As mitigações do catálogo são organizadas nas quatro categorias de Saeri et al. (2025): governança e supervisão; técnico e segurança; processos operacionais; transparência e responsabilização.
A15: CAT-2 | B15: B. Catálogo de mitigações (C2) | C15: OE6 | D15: =COUNTIF('Consolidação'!$H$2:$H$61,"Essencial") -> 0 | E15: =COUNTIF('Consolidação'!$H$2:$H$61,"Útil, mas não essencial") -> 0 | F15: =COUNTIF('Consolidação'!$H$2:$H$61,"Desnecessário") -> 0 | G15: =IF(ISNUMBER($C$5),(D15-$C$4/2)/($C$4/2),"-") -> - | H15: =IF(ISNUMBER($C$5),IF(D15>=$C$5,"sim","não"),"-") -> - | I15: Cada mitigação do catálogo indica os subdomínios de risco da taxonomia do MIT AI Risk Repository que ela reduz diretamente e a evidência esperada de sua aplicação.
A16: CAT-3 | B16: B. Catálogo de mitigações (C2) | C16: OE6 | D16: =COUNTIF('Consolidação'!$I$2:$I$61,"Essencial") -> 0 | E16: =COUNTIF('Consolidação'!$I$2:$I$61,"Útil, mas não essencial") -> 0 | F16: =COUNTIF('Consolidação'!$I$2:$I$61,"Desnecessário") -> 0 | G16: =IF(ISNUMBER($C$5),(D16-$C$4/2)/($C$4/2),"-") -> - | H16: =IF(ISNUMBER($C$5),IF(D16>=$C$5,"sim","não"),"-") -> - | I16: Cada mitigação do catálogo traz uma estimativa qualitativa de custo (baixo, médio ou alto) e o nível de incerteza dessa estimativa.
A17: DEF-C1 | B17: C. Protocolo de monitoramento (C3) | C17: OE3; OE6 | D17: =COUNTIF('Consolidação'!$J$2:$J$61,"Essencial") -> 0 | E17: =COUNTIF('Consolidação'!$J$2:$J$61,"Útil, mas não essencial") -> 0 | F17: =COUNTIF('Consolidação'!$J$2:$J$61,"Desnecessário") -> 0 | G17: =IF(ISNUMBER($C$5),(D17-$C$4/2)/($C$4/2),"-") -> - | H17: =IF(ISNUMBER($C$5),IF(D17>=$C$5,"sim","não"),"-") -> - | I17: A ocorrência é observada em um sistema de IA em operação, isto é, usado em decisão, interação ou processo real cujos efeitos alcançam pessoas ou bens reais, inclusive em piloto, implantação em etapas ou uso interno. Ocorrências em testes, avaliações ou exercícios controlados são resultados de teste.
A18: DEF-C2 | B18: C. Protocolo de monitoramento (C3) | C18: OE3; OE6 | D18: =COUNTIF('Consolidação'!$K$2:$K$61,"Essencial") -> 0 | E18: =COUNTIF('Consolidação'!$K$2:$K$61,"Útil, mas não essencial") -> 0 | F18: =COUNTIF('Consolidação'!$K$2:$K$61,"Desnecessário") -> 0 | G18: =IF(ISNUMBER($C$5),(D18-$C$4/2)/($C$4/2),"-") -> - | H18: =IF(ISNUMBER($C$5),IF(D18>=$C$5,"sim","não"),"-") -> - | I18: A ocorrência decorre do funcionamento, do uso ou de falha do sistema, inclusive quando ele opera conforme projetado.
A19: DEF-C3a | B19: C. Protocolo de monitoramento (C3) | C19: OE3; OE6 | D19: =COUNTIF('Consolidação'!$L$2:$L$61,"Essencial") -> 0 | E19: =COUNTIF('Consolidação'!$L$2:$L$61,"Útil, mas não essencial") -> 0 | F19: =COUNTIF('Consolidação'!$L$2:$L$61,"Desnecessário") -> 0 | G19: =IF(ISNUMBER($C$5),(D19-$C$4/2)/($C$4/2),"-") -> - | H19: =IF(ISNUMBER($C$5),IF(D19>=$C$5,"sim","não"),"-") -> - | I19: A ocorrência causou dano (incidente) ou poderia plausivelmente tê-lo causado (quase-incidente); ambos são eventos adversos.
A20: DEF-C3b | B20: C. Protocolo de monitoramento (C3) | C20: OE3; OE6 | D20: =COUNTIF('Consolidação'!$M$2:$M$61,"Essencial") -> 0 | E20: =COUNTIF('Consolidação'!$M$2:$M$61,"Útil, mas não essencial") -> 0 | F20: =COUNTIF('Consolidação'!$M$2:$M$61,"Desnecessário") -> 0 | G20: =IF(ISNUMBER($C$5),(D20-$C$4/2)/($C$4/2),"-") -> - | H20: =IF(ISNUMBER($C$5),IF(D20>=$C$5,"sim","não"),"-") -> - | I20: O dano considerado pode recair sobre pessoas ou grupos, sobre a organização que opera o sistema ou sobre o ecossistema, incluindo o meio ambiente.
A21: DEF-C4 | B21: C. Protocolo de monitoramento (C3) | C21: OE3; OE6 | D21: =COUNTIF('Consolidação'!$N$2:$N$61,"Essencial") -> 0 | E21: =COUNTIF('Consolidação'!$N$2:$N$61,"Útil, mas não essencial") -> 0 | F21: =COUNTIF('Consolidação'!$N$2:$N$61,"Desnecessário") -> 0 | G21: =IF(ISNUMBER($C$5),(D21-$C$4/2)/($C$4/2),"-") -> - | H21: =IF(ISNUMBER($C$5),IF(D21>=$C$5,"sim","não"),"-") -> - | I21: A ocorrência pode ser associada a ao menos um subdomínio da taxonomia de riscos adotada, haja ou não risco cadastrado nesse subdomínio.
A22: DEF-C5 | B22: C. Protocolo de monitoramento (C3) | C22: OE3; OE6 | D22: =COUNTIF('Consolidação'!$O$2:$O$61,"Essencial") -> 0 | E22: =COUNTIF('Consolidação'!$O$2:$O$61,"Útil, mas não essencial") -> 0 | F22: =COUNTIF('Consolidação'!$O$2:$O$61,"Desnecessário") -> 0 | G22: =IF(ISNUMBER($C$5),(D22-$C$4/2)/($C$4/2),"-") -> - | H22: =IF(ISNUMBER($C$5),IF(D22>=$C$5,"sim","não"),"-") -> - | I22: Basta a suspeita fundamentada para registrar. A relação causal é apurada na reavaliação do vínculo.
A23: DEF-C6 | B23: C. Protocolo de monitoramento (C3) | C23: OE3; OE6 | D23: =COUNTIF('Consolidação'!$P$2:$P$61,"Essencial") -> 0 | E23: =COUNTIF('Consolidação'!$P$2:$P$61,"Útil, mas não essencial") -> 0 | F23: =COUNTIF('Consolidação'!$P$2:$P$61,"Desnecessário") -> 0 | G23: =IF(ISNUMBER($C$5),(D23-$C$4/2)/($C$4/2),"-") -> - | H23: =IF(ISNUMBER($C$5),IF(D23>=$C$5,"sim","não"),"-") -> - | I23: Uma ocorrência barrada por mitigação antes de causar dano é registrada como quase-incidente, podendo indicar o vínculo que a interceptou.
A24: MON-1 | B24: C. Protocolo de monitoramento (C3) | C24: OE6 | D24: =COUNTIF('Consolidação'!$Q$2:$Q$61,"Essencial") -> 0 | E24: =COUNTIF('Consolidação'!$Q$2:$Q$61,"Útil, mas não essencial") -> 0 | F24: =COUNTIF('Consolidação'!$Q$2:$Q$61,"Desnecessário") -> 0 | G24: =IF(ISNUMBER($C$5),(D24-$C$4/2)/($C$4/2),"-") -> - | H24: =IF(ISNUMBER($C$5),IF(D24>=$C$5,"sim","não"),"-") -> - | I24: O registro de um evento adverso devolve à reavaliação os vínculos verificados do sistema cujo risco está em algum dos subdomínios do evento.
A25: MON-2 | B25: C. Protocolo de monitoramento (C3) | C25: OE6 | D25: =COUNTIF('Consolidação'!$R$2:$R$61,"Essencial") -> 0 | E25: =COUNTIF('Consolidação'!$R$2:$R$61,"Útil, mas não essencial") -> 0 | F25: =COUNTIF('Consolidação'!$R$2:$R$61,"Desnecessário") -> 0 | G25: =IF(ISNUMBER($C$5),(D25-$C$4/2)/($C$4/2),"-") -> - | H25: =IF(ISNUMBER($C$5),IF(D25>=$C$5,"sim","não"),"-") -> - | I25: O registro de uma mudança do sistema (nova versão do modelo ou alteração na base de dados) devolve à reavaliação os vínculos verificados dos subdomínios afetados, ou todos, quando os subdomínios afetados não são informados.
A26: MON-3 | B26: C. Protocolo de monitoramento (C3) | C26: OE6 | D26: =COUNTIF('Consolidação'!$S$2:$S$61,"Essencial") -> 0 | E26: =COUNTIF('Consolidação'!$S$2:$S$61,"Útil, mas não essencial") -> 0 | F26: =COUNTIF('Consolidação'!$S$2:$S$61,"Desnecessário") -> 0 | G26: =IF(ISNUMBER($C$5),(D26-$C$4/2)/($C$4/2),"-") -> - | H26: =IF(ISNUMBER($C$5),IF(D26>=$C$5,"sim","não"),"-") -> - | I26: A verificação de cada vínculo vale por um prazo proporcional à faixa de risco do sistema no EU AI Act; vencido o prazo, o vínculo volta à reavaliação.
A27: PRO-1 | B27: D. Protótipo (C4) | C27: OE6 | D27: =COUNTIF('Consolidação'!$T$2:$T$61,"Essencial") -> 0 | E27: =COUNTIF('Consolidação'!$T$2:$T$61,"Útil, mas não essencial") -> 0 | F27: =COUNTIF('Consolidação'!$T$2:$T$61,"Desnecessário") -> 0 | G27: =IF(ISNUMBER($C$5),(D27-$C$4/2)/($C$4/2),"-") -> - | H27: =IF(ISNUMBER($C$5),IF(D27>=$C$5,"sim","não"),"-") -> - | I27: O protótipo exporta, por sistema de IA, um relatório de rastreabilidade que liga riscos, mitigações, responsáveis, evidências, histórico de status, reavaliações, eventos adversos e mudanças do sistema.
A28: PRO-2 | B28: D. Protótipo (C4) | C28: OE6 | D28: =COUNTIF('Consolidação'!$U$2:$U$61,"Essencial") -> 0 | E28: =COUNTIF('Consolidação'!$U$2:$U$61,"Útil, mas não essencial") -> 0 | F28: =COUNTIF('Consolidação'!$U$2:$U$61,"Desnecessário") -> 0 | G28: =IF(ISNUMBER($C$5),(D28-$C$4/2)/($C$4/2),"-") -> - | H28: =IF(ISNUMBER($C$5),IF(D28>=$C$5,"sim","não"),"-") -> - | I28: A tela de acompanhamento do protótipo mostra os vínculos que aguardam reavaliação, separados pelo gatilho que os originou: vencimento, evento adverso, mudança do sistema, reclassificação ou decisão manual.
A29: PRO-3 | B29: D. Protótipo (C4) | C29: OE6 | D29: =COUNTIF('Consolidação'!$V$2:$V$61,"Essencial") -> 0 | E29: =COUNTIF('Consolidação'!$V$2:$V$61,"Útil, mas não essencial") -> 0 | F29: =COUNTIF('Consolidação'!$V$2:$V$61,"Desnecessário") -> 0 | G29: =IF(ISNUMBER($C$5),(D29-$C$4/2)/($C$4/2),"-") -> - | H29: =IF(ISNUMBER($C$5),IF(D29>=$C$5,"sim","não"),"-") -> - | I29: O protótipo alerta quando um evento adverso ou uma mudança do sistema aponta um subdomínio de risco sem risco cadastrado para o sistema.
A31: Critérios de sucesso e CVI
A32: Medida | C32: Itens | D32: Mantidos | E32: Atendido
A33: OE3 (itens da definição) | C33: =COUNTIF($C$9:$C$29,"*OE3*") -> 7 | D33: =COUNTIFS($C$9:$C$29,"*OE3*",$H$9:$H$29,"sim") -> 0 | E33: =IF(ISNUMBER($C$5),IF(AND(C33>0,D33=C33),"sim","não"),"-") -> -
A34: OE6 (todos os itens) | C34: =COUNTA($A$9:$A$29) -> 21 | D34: =COUNTIF($H$9:$H$29,"sim") -> 0 | E34: =IF(ISNUMBER($C$5),IF(D34=C34,"sim","não"),"-") -> -
A36: CVI | C36: Todos os itens | D36: Mantidos
A37: Geral | C37: =IF(ISNUMBER($C$5),AVERAGE($G$9:$G$29),"-") -> - | D37: =IF(ISNUMBER($C$5),IFERROR(AVERAGEIF($H$9:$H$29,"sim",$G$9:$G$29),"-"),"-") -> -
A38: A. Modelo de vínculo (C1) | C38: =IF(ISNUMBER($C$5),AVERAGEIF($B$9:$B$29,"A. Modelo de vínculo (C1)",$G$9:$G$29),"-") -> - | D38: =IF(ISNUMBER($C$5),IFERROR(AVERAGEIFS($G$9:$G$29,$B$9:$B$29,"A. Modelo de vínculo (C1)",$H$9:$H$29,"sim"),"-"),"-") -> -
A39: B. Catálogo de mitigações (C2) | C39: =IF(ISNUMBER($C$5),AVERAGEIF($B$9:$B$29,"B. Catálogo de mitigações (C2)",$G$9:$G$29),"-") -> - | D39: =IF(ISNUMBER($C$5),IFERROR(AVERAGEIFS($G$9:$G$29,$B$9:$B$29,"B. Catálogo de mitigações (C2)",$H$9:$H$29,"sim"),"-"),"-") -> -
A40: C. Protocolo de monitoramento (C3) | C40: =IF(ISNUMBER($C$5),AVERAGEIF($B$9:$B$29,"C. Protocolo de monitoramento (C3)",$G$9:$G$29),"-") -> - | D40: =IF(ISNUMBER($C$5),IFERROR(AVERAGEIFS($G$9:$G$29,$B$9:$B$29,"C. Protocolo de monitoramento (C3)",$H$9:$H$29,"sim"),"-"),"-") -> -
A41: D. Protótipo (C4) | C41: =IF(ISNUMBER($C$5),AVERAGEIF($B$9:$B$29,"D. Protótipo (C4)",$G$9:$G$29),"-") -> - | D41: =IF(ISNUMBER($C$5),IFERROR(AVERAGEIFS($G$9:$G$29,$B$9:$B$29,"D. Protótipo (C4)",$H$9:$H$29,"sim"),"-"),"-") -> -
A43: Intervalos de revisão (rodada 2)
A44: Faixa | C44: Protocolo (dias) | D44: Mediana | E44: 1º quartil | F44: 3º quartil | G44: Sustentado
A45: Alto risco | C45: 90 | D45: =IF(COUNT('Consolidação'!$W$2:$W$61)>0,MEDIAN('Consolidação'!$W$2:$W$61),"-") -> - | E45: =IF(COUNT('Consolidação'!$W$2:$W$61)>0,QUARTILE('Consolidação'!$W$2:$W$61,1),"-") -> - | F45: =IF(COUNT('Consolidação'!$W$2:$W$61)>0,QUARTILE('Consolidação'!$W$2:$W$61,3),"-") -> - | G45: =IF(COUNT('Consolidação'!$W$2:$W$61)>0,IF(AND(E45<=C45,C45<=F45),"sim","não"),"-") -> -
...
